+ module purge
+ '[' purge == load ']'
++ /usr/bin/modulecmd bash purge
+ eval
+ '[' purge == load ']'
+ module load anaconda/py3
+ '[' load == load ']'
+ /usr/bin/modulecmd bash list -l
+ tail -n +3
+ cut '-d ' -f1
++ /usr/bin/modulecmd bash load anaconda/py3
                                                                 
                                                                                
##############################################                                  
INFORMATION                                                                     
##############################################                                  
                                                                                
You have loaded the base anaconda environment. For specialized environments,    
you must first enable them with `source activate [env]`.                        
                                                                                
For a full list of environments, type `conda env list`                          
  
+ eval INCLUDE=/packages/7x/anaconda3/5.3.0/include ';export' 'INCLUDE;INFOPATH=/packages/7x/anaconda3/5.3.0/share/info' ';export' 'INFOPATH;LD_LIBRARY_PATH=/packages/7x/anaconda3/5.3.0/lib' ';export' 'LD_LIBRARY_PATH;LOADEDMODULES=anaconda/py3' ';export' 'LOADEDMODULES;MANPATH=/packages/7x/anaconda3/5.3.0/share/man:/usr/share/man:/usr/local/share/man' ';export' 'MANPATH;PATH=/packages/7x/anaconda3/5.3.0/bin:/usr/lib64/qt-3.3/bin:/home/ejakupov/perl5/bin:/packages/scripts:/packages/sysadmin/agave/scripts/:/usr/local/cuda/bin:/usr/local/bin:/usr/bin:/usr/local/sbin:/usr/sbin:/packages/7x/perl5lib/bin:/home/ejakupov/.local/bin:/home/ejakupov/bin' ';export' 'PATH;_LMFILES_=/usr/share/Modules/modulefiles/anaconda/py3' ';export' '_LMFILES_;unset' 'MODULEBUILDRC;unset' 'PERL5LIB;unset' 'PERL_LOCAL_LIB_ROOT;unset' 'PERL_MB_OPT;unset' 'PERL_MM_OPT;'
++ INCLUDE=/packages/7x/anaconda3/5.3.0/include
++ export INCLUDE
++ INFOPATH=/packages/7x/anaconda3/5.3.0/share/info
++ export INFOPATH
++ LD_LIBRARY_PATH=/packages/7x/anaconda3/5.3.0/lib
++ export LD_LIBRARY_PATH
++ LOADEDMODULES=anaconda/py3
++ export LOADEDMODULES
++ MANPATH=/packages/7x/anaconda3/5.3.0/share/man:/usr/share/man:/usr/local/share/man
++ export MANPATH
++ PATH=/packages/7x/anaconda3/5.3.0/bin:/usr/lib64/qt-3.3/bin:/home/ejakupov/perl5/bin:/packages/scripts:/packages/sysadmin/agave/scripts/:/usr/local/cuda/bin:/usr/local/bin:/usr/bin:/usr/local/sbin:/usr/sbin:/packages/7x/perl5lib/bin:/home/ejakupov/.local/bin:/home/ejakupov/bin
++ export PATH
++ _LMFILES_=/usr/share/Modules/modulefiles/anaconda/py3
++ export _LMFILES_
++ unset MODULEBUILDRC
++ unset PERL5LIB
++ unset PERL_LOCAL_LIB_ROOT
++ unset PERL_MB_OPT
++ unset PERL_MM_OPT
+ '[' load == load ']'
+ /usr/bin/modulecmd bash list -l
+ tail -n +3
+ cut '-d ' -f1
+ diff -c /tmp/ejakupov-prelist /tmp/ejakupov-postlist
+ grep --color=auto '^+'
+ sed 's/^+ //'
++ cat /tmp/ejakupov-difflist
+ for bobsyeruncle_module_xxx in '$(cat /tmp/${USER}-difflist)'
+ /packages/sysadmin/environment_modules/database/module_db.py load anaconda/py3
+ /bin/rm -f /tmp/ejakupov-prelist
+ /bin/rm -f /tmp/ejakupov-postlist
+ /bin/rm -f /tmp/ejakupov-difflist
+ /packages/sysadmin/slurm_scripts/module.py
+ module load hdf5/1.10.1-gnu-stock-openmpi-3.0.0
+ '[' load == load ']'
+ /usr/bin/modulecmd bash list -l
+ tail -n +3
+ cut '-d ' -f1
++ /usr/bin/modulecmd bash load hdf5/1.10.1-gnu-stock-openmpi-3.0.0


##############################################
INFORMATION
##############################################

OpenMPI uses mpirun or mpiexec by default.

To use srun, you must include the --mpi=pmi2 option.

(e.g. srun --mpi=pmi2 ./executable)

See the manpages for mpirun and srun for more
information (e.g. man srun).


+ eval HDF5_DIR=/packages/7x/hdf5/1.10.1/openmpi/3.0.0/gcc/stock ';export' 'HDF5_DIR;INCLUDE=/packages/7x/hdf5/1.10.1/openmpi/3.0.0/gcc/stock/include:/packages/7x/szip/2.1/include:/packages/7x/zlib/1.2.8/include:/packages/7x/openmpi/agave/3.0.0/gcc/stock/normal/include:/packages/7x/hwloc/1.11.8/include:/packages/7x/anaconda3/5.3.0/include' ';export' 'INCLUDE;INFOPATH=/packages/7x/zlib/1.2.8/share/info:/packages/7x/anaconda3/5.3.0/share/info' ';export' 'INFOPATH;JAVA_HOME=/packages/7x/java/8u162' ';export' 'JAVA_HOME;LD_LIBRARY_PATH=/packages/7x/hdf5/1.10.1/openmpi/3.0.0/gcc/stock/lib:/packages/7x/szip/2.1/lib:/packages/7x/zlib/1.2.8/lib:/packages/7x/openmpi/agave/3.0.0/gcc/stock/normal/lib:/packages/7x/hwloc/1.11.8/lib:/packages/7x/anaconda3/5.3.0/lib' ';export' 'LD_LIBRARY_PATH;LOADEDMODULES=anaconda/py3:java/latest:hwloc/1.11.8:openmpi/3.0.0-gnu-stock:zlib/1.2.8:szip/2.1:hdf5/1.10.1-gnu-stock-openmpi-3.0.0' ';export' 'LOADEDMODULES;MANPATH=/packages/7x/zlib/1.2.8/share/man:/packages/7x/openmpi/agave/3.0.0/gcc/stock/normal/share/man:/packages/7x/hwloc/1.11.8/share/man:/packages/7x/java/8u162/man:/packages/7x/anaconda3/5.3.0/share/man:/usr/share/man:/usr/local/share/man' ';export' 'MANPATH;PATH=/packages/7x/hdf5/1.10.1/openmpi/3.0.0/gcc/stock/bin:/packages/7x/openmpi/agave/3.0.0/gcc/stock/normal/bin:/packages/7x/hwloc/1.11.8/bin:/packages/7x/java/8u162/bin:/packages/7x/anaconda3/5.3.0/bin:/usr/lib64/qt-3.3/bin:/home/ejakupov/perl5/bin:/packages/scripts:/packages/sysadmin/agave/scripts/:/usr/local/cuda/bin:/usr/local/bin:/usr/bin:/usr/local/sbin:/usr/sbin:/packages/7x/perl5lib/bin:/home/ejakupov/.local/bin:/home/ejakupov/bin' ';export' 'PATH;ZLIBCFLAGS=\' -I/packages/7x/zlib/1.2.8/include ';export' 'ZLIBCFLAGS;ZLIBLDFLAGS=\' -L/packages/7x/zlib/1.2.8/lib ';export' 'ZLIBLDFLAGS;_LMFILES_=/usr/share/Modules/modulefiles/anaconda/py3:/usr/share/Modules/modulefiles/java/latest:/usr/share/Modules/modulefiles/hwloc/1.11.8:/usr/share/Modules/modulefiles/openmpi/3.0.0-gnu-stock:/usr/share/Modules/modulefiles/zlib/1.2.8:/usr/share/Modules/modulefiles/szip/2.1:/usr/share/Modules/modulefiles/hdf5/1.10.1-gnu-stock-openmpi-3.0.0' ';export' '_LMFILES_;'
++ HDF5_DIR=/packages/7x/hdf5/1.10.1/openmpi/3.0.0/gcc/stock
++ export HDF5_DIR
++ INCLUDE=/packages/7x/hdf5/1.10.1/openmpi/3.0.0/gcc/stock/include:/packages/7x/szip/2.1/include:/packages/7x/zlib/1.2.8/include:/packages/7x/openmpi/agave/3.0.0/gcc/stock/normal/include:/packages/7x/hwloc/1.11.8/include:/packages/7x/anaconda3/5.3.0/include
++ export INCLUDE
++ INFOPATH=/packages/7x/zlib/1.2.8/share/info:/packages/7x/anaconda3/5.3.0/share/info
++ export INFOPATH
++ JAVA_HOME=/packages/7x/java/8u162
++ export JAVA_HOME
++ LD_LIBRARY_PATH=/packages/7x/hdf5/1.10.1/openmpi/3.0.0/gcc/stock/lib:/packages/7x/szip/2.1/lib:/packages/7x/zlib/1.2.8/lib:/packages/7x/openmpi/agave/3.0.0/gcc/stock/normal/lib:/packages/7x/hwloc/1.11.8/lib:/packages/7x/anaconda3/5.3.0/lib
++ export LD_LIBRARY_PATH
++ LOADEDMODULES=anaconda/py3:java/latest:hwloc/1.11.8:openmpi/3.0.0-gnu-stock:zlib/1.2.8:szip/2.1:hdf5/1.10.1-gnu-stock-openmpi-3.0.0
++ export LOADEDMODULES
++ MANPATH=/packages/7x/zlib/1.2.8/share/man:/packages/7x/openmpi/agave/3.0.0/gcc/stock/normal/share/man:/packages/7x/hwloc/1.11.8/share/man:/packages/7x/java/8u162/man:/packages/7x/anaconda3/5.3.0/share/man:/usr/share/man:/usr/local/share/man
++ export MANPATH
++ PATH=/packages/7x/hdf5/1.10.1/openmpi/3.0.0/gcc/stock/bin:/packages/7x/openmpi/agave/3.0.0/gcc/stock/normal/bin:/packages/7x/hwloc/1.11.8/bin:/packages/7x/java/8u162/bin:/packages/7x/anaconda3/5.3.0/bin:/usr/lib64/qt-3.3/bin:/home/ejakupov/perl5/bin:/packages/scripts:/packages/sysadmin/agave/scripts/:/usr/local/cuda/bin:/usr/local/bin:/usr/bin:/usr/local/sbin:/usr/sbin:/packages/7x/perl5lib/bin:/home/ejakupov/.local/bin:/home/ejakupov/bin
++ export PATH
++ ZLIBCFLAGS=' -I/packages/7x/zlib/1.2.8/include'
++ export ZLIBCFLAGS
++ ZLIBLDFLAGS=' -L/packages/7x/zlib/1.2.8/lib'
++ export ZLIBLDFLAGS
++ _LMFILES_=/usr/share/Modules/modulefiles/anaconda/py3:/usr/share/Modules/modulefiles/java/latest:/usr/share/Modules/modulefiles/hwloc/1.11.8:/usr/share/Modules/modulefiles/openmpi/3.0.0-gnu-stock:/usr/share/Modules/modulefiles/zlib/1.2.8:/usr/share/Modules/modulefiles/szip/2.1:/usr/share/Modules/modulefiles/hdf5/1.10.1-gnu-stock-openmpi-3.0.0
++ export _LMFILES_
+ '[' load == load ']'
+ /usr/bin/modulecmd bash list -l
+ tail -n +3
+ cut '-d ' -f1
+ diff -c /tmp/ejakupov-prelist /tmp/ejakupov-postlist
+ grep --color=auto '^+'
+ sed 's/^+ //'
++ cat /tmp/ejakupov-difflist
+ for bobsyeruncle_module_xxx in '$(cat /tmp/${USER}-difflist)'
+ /packages/sysadmin/environment_modules/database/module_db.py load java/latest
+ for bobsyeruncle_module_xxx in '$(cat /tmp/${USER}-difflist)'
+ /packages/sysadmin/environment_modules/database/module_db.py load hwloc/1.11.8
+ for bobsyeruncle_module_xxx in '$(cat /tmp/${USER}-difflist)'
+ /packages/sysadmin/environment_modules/database/module_db.py load openmpi/3.0.0-gnu-stock
+ for bobsyeruncle_module_xxx in '$(cat /tmp/${USER}-difflist)'
+ /packages/sysadmin/environment_modules/database/module_db.py load zlib/1.2.8
+ for bobsyeruncle_module_xxx in '$(cat /tmp/${USER}-difflist)'
+ /packages/sysadmin/environment_modules/database/module_db.py load szip/2.1
+ for bobsyeruncle_module_xxx in '$(cat /tmp/${USER}-difflist)'
+ /packages/sysadmin/environment_modules/database/module_db.py load hdf5/1.10.1-gnu-stock-openmpi-3.0.0
+ /bin/rm -f /tmp/ejakupov-prelist
+ /bin/rm -f /tmp/ejakupov-postlist
+ /bin/rm -f /tmp/ejakupov-difflist
+ /packages/sysadmin/slurm_scripts/module.py
+ source activate mda2
++ _CONDA_ROOT=/packages/7x/anaconda3/5.3.0
++ . /packages/7x/anaconda3/5.3.0/etc/profile.d/conda.sh
+++ export CONDA_EXE=/packages/7x/anaconda3/5.3.0/bin/conda
+++ CONDA_EXE=/packages/7x/anaconda3/5.3.0/bin/conda
+++ export _CE_M=
+++ _CE_M=
+++ export _CE_CONDA=
+++ _CE_CONDA=
+++ export CONDA_PYTHON_EXE=/packages/7x/anaconda3/5.3.0/bin/python
+++ CONDA_PYTHON_EXE=/packages/7x/anaconda3/5.3.0/bin/python
+++ '[' -z '' ']'
+++ export CONDA_SHLVL=0
+++ CONDA_SHLVL=0
+++ '[' -n x ']'
+++ '[' -n '' ']'
+++++ dirname /packages/7x/anaconda3/5.3.0/bin/conda
++++ dirname /packages/7x/anaconda3/5.3.0/bin
+++ PATH=/packages/7x/anaconda3/5.3.0/condabin:/packages/7x/hdf5/1.10.1/openmpi/3.0.0/gcc/stock/bin:/packages/7x/openmpi/agave/3.0.0/gcc/stock/normal/bin:/packages/7x/hwloc/1.11.8/bin:/packages/7x/java/8u162/bin:/packages/7x/anaconda3/5.3.0/bin:/usr/lib64/qt-3.3/bin:/home/ejakupov/perl5/bin:/packages/scripts:/packages/sysadmin/agave/scripts/:/usr/local/cuda/bin:/usr/local/bin:/usr/bin:/usr/local/sbin:/usr/sbin:/packages/7x/perl5lib/bin:/home/ejakupov/.local/bin:/home/ejakupov/bin
+++ export PATH
+++ '[' -z '' ']'
+++ PS1=
++ conda activate mda2
++ '[' 2 -lt 1 ']'
++ local cmd=activate
++ shift
++ case "$cmd" in
++ __conda_activate activate mda2
++ '[' -n '' ']'
++ local cmd=activate
++ shift
++ local ask_conda
++ OLDPATH=/packages/7x/anaconda3/5.3.0/condabin:/packages/7x/hdf5/1.10.1/openmpi/3.0.0/gcc/stock/bin:/packages/7x/openmpi/agave/3.0.0/gcc/stock/normal/bin:/packages/7x/hwloc/1.11.8/bin:/packages/7x/java/8u162/bin:/packages/7x/anaconda3/5.3.0/bin:/usr/lib64/qt-3.3/bin:/home/ejakupov/perl5/bin:/packages/scripts:/packages/sysadmin/agave/scripts/:/usr/local/cuda/bin:/usr/local/bin:/usr/bin:/usr/local/sbin:/usr/sbin:/packages/7x/perl5lib/bin:/home/ejakupov/.local/bin:/home/ejakupov/bin
++ __add_sys_prefix_to_path
++ '[' -n '' ']'
+++ dirname /packages/7x/anaconda3/5.3.0/bin/conda
++ SYSP=/packages/7x/anaconda3/5.3.0/bin
+++ dirname /packages/7x/anaconda3/5.3.0/bin
++ SYSP=/packages/7x/anaconda3/5.3.0
++ '[' -n '' ']'
++ PATH=/packages/7x/anaconda3/5.3.0/bin:/packages/7x/anaconda3/5.3.0/condabin:/packages/7x/hdf5/1.10.1/openmpi/3.0.0/gcc/stock/bin:/packages/7x/openmpi/agave/3.0.0/gcc/stock/normal/bin:/packages/7x/hwloc/1.11.8/bin:/packages/7x/java/8u162/bin:/packages/7x/anaconda3/5.3.0/bin:/usr/lib64/qt-3.3/bin:/home/ejakupov/perl5/bin:/packages/scripts:/packages/sysadmin/agave/scripts/:/usr/local/cuda/bin:/usr/local/bin:/usr/bin:/usr/local/sbin:/usr/sbin:/packages/7x/perl5lib/bin:/home/ejakupov/.local/bin:/home/ejakupov/bin
++ export PATH
+++ PS1=
+++ /packages/7x/anaconda3/5.3.0/bin/conda shell.posix activate mda2
++ ask_conda='PS1='\''(mda2) '\''
export PATH='\''/home/ejakupov/.conda/envs/mda2/bin:/packages/7x/anaconda3/5.3.0/condabin:/packages/7x/hdf5/1.10.1/openmpi/3.0.0/gcc/stock/bin:/packages/7x/openmpi/agave/3.0.0/gcc/stock/normal/bin:/packages/7x/hwloc/1.11.8/bin:/packages/7x/java/8u162/bin:/packages/7x/anaconda3/5.3.0/bin:/usr/lib64/qt-3.3/bin:/home/ejakupov/perl5/bin:/packages/scripts:/packages/sysadmin/agave/scripts:/usr/local/cuda/bin:/usr/local/bin:/usr/bin:/usr/local/sbin:/usr/sbin:/packages/7x/perl5lib/bin:/home/ejakupov/.local/bin:/home/ejakupov/bin'\''
export CONDA_PREFIX='\''/home/ejakupov/.conda/envs/mda2'\''
export CONDA_SHLVL='\''1'\''
export CONDA_DEFAULT_ENV='\''mda2'\''
export CONDA_PROMPT_MODIFIER='\''(mda2) '\''
export CONDA_EXE='\''/packages/7x/anaconda3/5.3.0/bin/conda'\''
export _CE_M='\'''\''
export _CE_CONDA='\'''\''
export CONDA_PYTHON_EXE='\''/packages/7x/anaconda3/5.3.0/bin/python'\'''
++ PATH=/packages/7x/anaconda3/5.3.0/condabin:/packages/7x/hdf5/1.10.1/openmpi/3.0.0/gcc/stock/bin:/packages/7x/openmpi/agave/3.0.0/gcc/stock/normal/bin:/packages/7x/hwloc/1.11.8/bin:/packages/7x/java/8u162/bin:/packages/7x/anaconda3/5.3.0/bin:/usr/lib64/qt-3.3/bin:/home/ejakupov/perl5/bin:/packages/scripts:/packages/sysadmin/agave/scripts/:/usr/local/cuda/bin:/usr/local/bin:/usr/bin:/usr/local/sbin:/usr/sbin:/packages/7x/perl5lib/bin:/home/ejakupov/.local/bin:/home/ejakupov/bin
++ eval 'PS1='\''(mda2) '\''
export PATH='\''/home/ejakupov/.conda/envs/mda2/bin:/packages/7x/anaconda3/5.3.0/condabin:/packages/7x/hdf5/1.10.1/openmpi/3.0.0/gcc/stock/bin:/packages/7x/openmpi/agave/3.0.0/gcc/stock/normal/bin:/packages/7x/hwloc/1.11.8/bin:/packages/7x/java/8u162/bin:/packages/7x/anaconda3/5.3.0/bin:/usr/lib64/qt-3.3/bin:/home/ejakupov/perl5/bin:/packages/scripts:/packages/sysadmin/agave/scripts:/usr/local/cuda/bin:/usr/local/bin:/usr/bin:/usr/local/sbin:/usr/sbin:/packages/7x/perl5lib/bin:/home/ejakupov/.local/bin:/home/ejakupov/bin'\''
export CONDA_PREFIX='\''/home/ejakupov/.conda/envs/mda2'\''
export CONDA_SHLVL='\''1'\''
export CONDA_DEFAULT_ENV='\''mda2'\''
export CONDA_PROMPT_MODIFIER='\''(mda2) '\''
export CONDA_EXE='\''/packages/7x/anaconda3/5.3.0/bin/conda'\''
export _CE_M='\'''\''
export _CE_CONDA='\'''\''
export CONDA_PYTHON_EXE='\''/packages/7x/anaconda3/5.3.0/bin/python'\'''
+++ PS1='(mda2) '
+++ export PATH=/home/ejakupov/.conda/envs/mda2/bin:/packages/7x/anaconda3/5.3.0/condabin:/packages/7x/hdf5/1.10.1/openmpi/3.0.0/gcc/stock/bin:/packages/7x/openmpi/agave/3.0.0/gcc/stock/normal/bin:/packages/7x/hwloc/1.11.8/bin:/packages/7x/java/8u162/bin:/packages/7x/anaconda3/5.3.0/bin:/usr/lib64/qt-3.3/bin:/home/ejakupov/perl5/bin:/packages/scripts:/packages/sysadmin/agave/scripts:/usr/local/cuda/bin:/usr/local/bin:/usr/bin:/usr/local/sbin:/usr/sbin:/packages/7x/perl5lib/bin:/home/ejakupov/.local/bin:/home/ejakupov/bin
+++ PATH=/home/ejakupov/.conda/envs/mda2/bin:/packages/7x/anaconda3/5.3.0/condabin:/packages/7x/hdf5/1.10.1/openmpi/3.0.0/gcc/stock/bin:/packages/7x/openmpi/agave/3.0.0/gcc/stock/normal/bin:/packages/7x/hwloc/1.11.8/bin:/packages/7x/java/8u162/bin:/packages/7x/anaconda3/5.3.0/bin:/usr/lib64/qt-3.3/bin:/home/ejakupov/perl5/bin:/packages/scripts:/packages/sysadmin/agave/scripts:/usr/local/cuda/bin:/usr/local/bin:/usr/bin:/usr/local/sbin:/usr/sbin:/packages/7x/perl5lib/bin:/home/ejakupov/.local/bin:/home/ejakupov/bin
+++ export CONDA_PREFIX=/home/ejakupov/.conda/envs/mda2
+++ CONDA_PREFIX=/home/ejakupov/.conda/envs/mda2
+++ export CONDA_SHLVL=1
+++ CONDA_SHLVL=1
+++ export CONDA_DEFAULT_ENV=mda2
+++ CONDA_DEFAULT_ENV=mda2
+++ export 'CONDA_PROMPT_MODIFIER=(mda2) '
+++ CONDA_PROMPT_MODIFIER='(mda2) '
+++ export CONDA_EXE=/packages/7x/anaconda3/5.3.0/bin/conda
+++ CONDA_EXE=/packages/7x/anaconda3/5.3.0/bin/conda
+++ export _CE_M=
+++ _CE_M=
+++ export _CE_CONDA=
+++ _CE_CONDA=
+++ export CONDA_PYTHON_EXE=/packages/7x/anaconda3/5.3.0/bin/python
+++ CONDA_PYTHON_EXE=/packages/7x/anaconda3/5.3.0/bin/python
++ __conda_hashr
++ '[' -n '' ']'
++ '[' -n '' ']'
++ hash -r
+ testdir=/scratch/ejakupov/Agave/temp/7077943
+ export OMP_NUM_THREADS=1
+ OMP_NUM_THREADS=1
+ mpiexec -n 56 python -W ignore /scratch/ejakupov/Agave/benchmarks/in_memory_2/scripts/benchmark.py /scratch/ejakupov/Agave/temp/7077943/YiiP_system.pdb /scratch/ejakupov/Agave/temp/7077943/YiiP_system_9ns_center100x.h5md trial_1/2node_3
Traceback (most recent call last):
  File "/scratch/ejakupov/Agave/benchmarks/in_memory_2/scripts/benchmark.py", line 208, in <module>
    times_array, rmsd_array = benchmark(topology, trajectory)
  File "/scratch/ejakupov/Agave/benchmarks/in_memory_2/scripts/benchmark.py", line 48, in benchmark
    u.transfer_to_memory(start=start, stop=stop, step=1)
  File "/home/ejakupov/mdanalysis/package/MDAnalysis/core/universe.py", line 593, in transfer_to_memory
    coordinates = np.zeros((n_frames, n_atoms, 3), dtype=np.float32)
MemoryError: Unable to allocate 2.01 GiB for an array with shape (1609, 111815, 3) and data type float32
Traceback (most recent call last):
  File "/scratch/ejakupov/Agave/benchmarks/in_memory_2/scripts/benchmark.py", line 208, in <module>
    times_array, rmsd_array = benchmark(topology, trajectory)
  File "/scratch/ejakupov/Agave/benchmarks/in_memory_2/scripts/benchmark.py", line 48, in benchmark
    u.transfer_to_memory(start=start, stop=stop, step=1)
  File "/home/ejakupov/mdanalysis/package/MDAnalysis/core/universe.py", line 593, in transfer_to_memory
    coordinates = np.zeros((n_frames, n_atoms, 3), dtype=np.float32)
MemoryError: Unable to allocate 2.01 GiB for an array with shape (1609, 111815, 3) and data type float32
Traceback (most recent call last):
  File "/scratch/ejakupov/Agave/benchmarks/in_memory_2/scripts/benchmark.py", line 208, in <module>
    times_array, rmsd_array = benchmark(topology, trajectory)
  File "/scratch/ejakupov/Agave/benchmarks/in_memory_2/scripts/benchmark.py", line 48, in benchmark
    u.transfer_to_memory(start=start, stop=stop, step=1)
  File "/home/ejakupov/mdanalysis/package/MDAnalysis/core/universe.py", line 593, in transfer_to_memory
    coordinates = np.zeros((n_frames, n_atoms, 3), dtype=np.float32)
MemoryError: Unable to allocate 2.01 GiB for an array with shape (1609, 111815, 3) and data type float32
Traceback (most recent call last):
  File "/scratch/ejakupov/Agave/benchmarks/in_memory_2/scripts/benchmark.py", line 208, in <module>
    times_array, rmsd_array = benchmark(topology, trajectory)
  File "/scratch/ejakupov/Agave/benchmarks/in_memory_2/scripts/benchmark.py", line 48, in benchmark
    u.transfer_to_memory(start=start, stop=stop, step=1)
  File "/home/ejakupov/mdanalysis/package/MDAnalysis/core/universe.py", line 593, in transfer_to_memory
    coordinates = np.zeros((n_frames, n_atoms, 3), dtype=np.float32)
MemoryError: Unable to allocate 2.01 GiB for an array with shape (1608, 111815, 3) and data type float32
Traceback (most recent call last):
  File "/scratch/ejakupov/Agave/benchmarks/in_memory_2/scripts/benchmark.py", line 208, in <module>
    times_array, rmsd_array = benchmark(topology, trajectory)
  File "/scratch/ejakupov/Agave/benchmarks/in_memory_2/scripts/benchmark.py", line 48, in benchmark
    u.transfer_to_memory(start=start, stop=stop, step=1)
  File "/home/ejakupov/mdanalysis/package/MDAnalysis/core/universe.py", line 593, in transfer_to_memory
    coordinates = np.zeros((n_frames, n_atoms, 3), dtype=np.float32)
MemoryError: Unable to allocate 2.01 GiB for an array with shape (1609, 111815, 3) and data type float32
Traceback (most recent call last):
  File "/scratch/ejakupov/Agave/benchmarks/in_memory_2/scripts/benchmark.py", line 208, in <module>
    times_array, rmsd_array = benchmark(topology, trajectory)
  File "/scratch/ejakupov/Agave/benchmarks/in_memory_2/scripts/benchmark.py", line 48, in benchmark
    u.transfer_to_memory(start=start, stop=stop, step=1)
  File "/home/ejakupov/mdanalysis/package/MDAnalysis/core/universe.py", line 593, in transfer_to_memory
    coordinates = np.zeros((n_frames, n_atoms, 3), dtype=np.float32)
MemoryError: Unable to allocate 2.01 GiB for an array with shape (1609, 111815, 3) and data type float32
Traceback (most recent call last):
  File "/scratch/ejakupov/Agave/benchmarks/in_memory_2/scripts/benchmark.py", line 208, in <module>
    times_array, rmsd_array = benchmark(topology, trajectory)
  File "/scratch/ejakupov/Agave/benchmarks/in_memory_2/scripts/benchmark.py", line 48, in benchmark
    u.transfer_to_memory(start=start, stop=stop, step=1)
  File "/home/ejakupov/mdanalysis/package/MDAnalysis/core/universe.py", line 593, in transfer_to_memory
    coordinates = np.zeros((n_frames, n_atoms, 3), dtype=np.float32)
MemoryError: Unable to allocate 2.01 GiB for an array with shape (1608, 111815, 3) and data type float32
Traceback (most recent call last):
  File "/scratch/ejakupov/Agave/benchmarks/in_memory_2/scripts/benchmark.py", line 208, in <module>
    times_array, rmsd_array = benchmark(topology, trajectory)
  File "/scratch/ejakupov/Agave/benchmarks/in_memory_2/scripts/benchmark.py", line 48, in benchmark
    u.transfer_to_memory(start=start, stop=stop, step=1)
  File "/home/ejakupov/mdanalysis/package/MDAnalysis/core/universe.py", line 605, in transfer_to_memory
    np.copyto(coordinates, group['position/value'][()])
  File "h5py/_objects.pyx", line 54, in h5py._objects.with_phil.wrapper
  File "h5py/_objects.pyx", line 55, in h5py._objects.with_phil.wrapper
  File "/home/ejakupov/.conda/envs/mda2/lib/python3.8/site-packages/h5py-2.9.0-py3.8-linux-x86_64.egg/h5py/_hl/dataset.py", line 562, in __getitem__
    arr = numpy.ndarray(mshape, new_dtype, order='C')
MemoryError: Unable to allocate 113. GiB for an array with shape (90100, 111815, 3) and data type float32
Traceback (most recent call last):
  File "/scratch/ejakupov/Agave/benchmarks/in_memory_2/scripts/benchmark.py", line 208, in <module>
    times_array, rmsd_array = benchmark(topology, trajectory)
  File "/scratch/ejakupov/Agave/benchmarks/in_memory_2/scripts/benchmark.py", line 48, in benchmark
    u.transfer_to_memory(start=start, stop=stop, step=1)
  File "/home/ejakupov/mdanalysis/package/MDAnalysis/core/universe.py", line 605, in transfer_to_memory
    np.copyto(coordinates, group['position/value'][()])
  File "h5py/_objects.pyx", line 54, in h5py._objects.with_phil.wrapper
  File "h5py/_objects.pyx", line 55, in h5py._objects.with_phil.wrapper
  File "/home/ejakupov/.conda/envs/mda2/lib/python3.8/site-packages/h5py-2.9.0-py3.8-linux-x86_64.egg/h5py/_hl/dataset.py", line 562, in __getitem__
    arr = numpy.ndarray(mshape, new_dtype, order='C')
MemoryError: Unable to allocate 113. GiB for an array with shape (90100, 111815, 3) and data type float32
Traceback (most recent call last):
  File "/scratch/ejakupov/Agave/benchmarks/in_memory_2/scripts/benchmark.py", line 208, in <module>
    times_array, rmsd_array = benchmark(topology, trajectory)
  File "/scratch/ejakupov/Agave/benchmarks/in_memory_2/scripts/benchmark.py", line 48, in benchmark
    u.transfer_to_memory(start=start, stop=stop, step=1)
  File "/home/ejakupov/mdanalysis/package/MDAnalysis/core/universe.py", line 605, in transfer_to_memory
    np.copyto(coordinates, group['position/value'][()])
  File "h5py/_objects.pyx", line 54, in h5py._objects.with_phil.wrapper
  File "h5py/_objects.pyx", line 55, in h5py._objects.with_phil.wrapper
  File "/home/ejakupov/.conda/envs/mda2/lib/python3.8/site-packages/h5py-2.9.0-py3.8-linux-x86_64.egg/h5py/_hl/dataset.py", line 562, in __getitem__
    arr = numpy.ndarray(mshape, new_dtype, order='C')
MemoryError: Unable to allocate 113. GiB for an array with shape (90100, 111815, 3) and data type float32
Traceback (most recent call last):
  File "/scratch/ejakupov/Agave/benchmarks/in_memory_2/scripts/benchmark.py", line 208, in <module>
    times_array, rmsd_array = benchmark(topology, trajectory)
  File "/scratch/ejakupov/Agave/benchmarks/in_memory_2/scripts/benchmark.py", line 48, in benchmark
    u.transfer_to_memory(start=start, stop=stop, step=1)
  File "/home/ejakupov/mdanalysis/package/MDAnalysis/core/universe.py", line 605, in transfer_to_memory
    np.copyto(coordinates, group['position/value'][()])
  File "h5py/_objects.pyx", line 54, in h5py._objects.with_phil.wrapper
  File "h5py/_objects.pyx", line 55, in h5py._objects.with_phil.wrapper
  File "/home/ejakupov/.conda/envs/mda2/lib/python3.8/site-packages/h5py-2.9.0-py3.8-linux-x86_64.egg/h5py/_hl/dataset.py", line 562, in __getitem__
    arr = numpy.ndarray(mshape, new_dtype, order='C')
MemoryError: Unable to allocate 113. GiB for an array with shape (90100, 111815, 3) and data type float32
Traceback (most recent call last):
  File "/scratch/ejakupov/Agave/benchmarks/in_memory_2/scripts/benchmark.py", line 208, in <module>
    times_array, rmsd_array = benchmark(topology, trajectory)
  File "/scratch/ejakupov/Agave/benchmarks/in_memory_2/scripts/benchmark.py", line 48, in benchmark
    u.transfer_to_memory(start=start, stop=stop, step=1)
  File "/home/ejakupov/mdanalysis/package/MDAnalysis/core/universe.py", line 605, in transfer_to_memory
    np.copyto(coordinates, group['position/value'][()])
  File "h5py/_objects.pyx", line 54, in h5py._objects.with_phil.wrapper
  File "h5py/_objects.pyx", line 55, in h5py._objects.with_phil.wrapper
  File "/home/ejakupov/.conda/envs/mda2/lib/python3.8/site-packages/h5py-2.9.0-py3.8-linux-x86_64.egg/h5py/_hl/dataset.py", line 562, in __getitem__
    arr = numpy.ndarray(mshape, new_dtype, order='C')
MemoryError: Unable to allocate 113. GiB for an array with shape (90100, 111815, 3) and data type float32
Traceback (most recent call last):
  File "/scratch/ejakupov/Agave/benchmarks/in_memory_2/scripts/benchmark.py", line 208, in <module>
    times_array, rmsd_array = benchmark(topology, trajectory)
  File "/scratch/ejakupov/Agave/benchmarks/in_memory_2/scripts/benchmark.py", line 48, in benchmark
    u.transfer_to_memory(start=start, stop=stop, step=1)
  File "/home/ejakupov/mdanalysis/package/MDAnalysis/core/universe.py", line 605, in transfer_to_memory
    np.copyto(coordinates, group['position/value'][()])
  File "h5py/_objects.pyx", line 54, in h5py._objects.with_phil.wrapper
  File "h5py/_objects.pyx", line 55, in h5py._objects.with_phil.wrapper
  File "/home/ejakupov/.conda/envs/mda2/lib/python3.8/site-packages/h5py-2.9.0-py3.8-linux-x86_64.egg/h5py/_hl/dataset.py", line 562, in __getitem__
    arr = numpy.ndarray(mshape, new_dtype, order='C')
MemoryError: Unable to allocate 113. GiB for an array with shape (90100, 111815, 3) and data type float32
Traceback (most recent call last):
  File "/scratch/ejakupov/Agave/benchmarks/in_memory_2/scripts/benchmark.py", line 208, in <module>
    times_array, rmsd_array = benchmark(topology, trajectory)
  File "/scratch/ejakupov/Agave/benchmarks/in_memory_2/scripts/benchmark.py", line 48, in benchmark
    u.transfer_to_memory(start=start, stop=stop, step=1)
  File "/home/ejakupov/mdanalysis/package/MDAnalysis/core/universe.py", line 605, in transfer_to_memory
    np.copyto(coordinates, group['position/value'][()])
  File "h5py/_objects.pyx", line 54, in h5py._objects.with_phil.wrapper
  File "h5py/_objects.pyx", line 55, in h5py._objects.with_phil.wrapper
  File "/home/ejakupov/.conda/envs/mda2/lib/python3.8/site-packages/h5py-2.9.0-py3.8-linux-x86_64.egg/h5py/_hl/dataset.py", line 562, in __getitem__
    arr = numpy.ndarray(mshape, new_dtype, order='C')
MemoryError: Unable to allocate 113. GiB for an array with shape (90100, 111815, 3) and data type float32
Traceback (most recent call last):
  File "/scratch/ejakupov/Agave/benchmarks/in_memory_2/scripts/benchmark.py", line 208, in <module>
    times_array, rmsd_array = benchmark(topology, trajectory)
  File "/scratch/ejakupov/Agave/benchmarks/in_memory_2/scripts/benchmark.py", line 48, in benchmark
    u.transfer_to_memory(start=start, stop=stop, step=1)
  File "/home/ejakupov/mdanalysis/package/MDAnalysis/core/universe.py", line 605, in transfer_to_memory
    np.copyto(coordinates, group['position/value'][()])
  File "h5py/_objects.pyx", line 54, in h5py._objects.with_phil.wrapper
  File "h5py/_objects.pyx", line 55, in h5py._objects.with_phil.wrapper
  File "/home/ejakupov/.conda/envs/mda2/lib/python3.8/site-packages/h5py-2.9.0-py3.8-linux-x86_64.egg/h5py/_hl/dataset.py", line 562, in __getitem__
    arr = numpy.ndarray(mshape, new_dtype, order='C')
MemoryError: Unable to allocate 113. GiB for an array with shape (90100, 111815, 3) and data type float32
Traceback (most recent call last):
  File "/scratch/ejakupov/Agave/benchmarks/in_memory_2/scripts/benchmark.py", line 208, in <module>
    times_array, rmsd_array = benchmark(topology, trajectory)
  File "/scratch/ejakupov/Agave/benchmarks/in_memory_2/scripts/benchmark.py", line 48, in benchmark
    u.transfer_to_memory(start=start, stop=stop, step=1)
  File "/home/ejakupov/mdanalysis/package/MDAnalysis/core/universe.py", line 605, in transfer_to_memory
    np.copyto(coordinates, group['position/value'][()])
  File "h5py/_objects.pyx", line 54, in h5py._objects.with_phil.wrapper
  File "h5py/_objects.pyx", line 55, in h5py._objects.with_phil.wrapper
  File "/home/ejakupov/.conda/envs/mda2/lib/python3.8/site-packages/h5py-2.9.0-py3.8-linux-x86_64.egg/h5py/_hl/dataset.py", line 562, in __getitem__
    arr = numpy.ndarray(mshape, new_dtype, order='C')
MemoryError: Unable to allocate 113. GiB for an array with shape (90100, 111815, 3) and data type float32
Traceback (most recent call last):
  File "/scratch/ejakupov/Agave/benchmarks/in_memory_2/scripts/benchmark.py", line 208, in <module>
    times_array, rmsd_array = benchmark(topology, trajectory)
  File "/scratch/ejakupov/Agave/benchmarks/in_memory_2/scripts/benchmark.py", line 48, in benchmark
    u.transfer_to_memory(start=start, stop=stop, step=1)
  File "/home/ejakupov/mdanalysis/package/MDAnalysis/core/universe.py", line 605, in transfer_to_memory
    np.copyto(coordinates, group['position/value'][()])
  File "h5py/_objects.pyx", line 54, in h5py._objects.with_phil.wrapper
  File "h5py/_objects.pyx", line 55, in h5py._objects.with_phil.wrapper
  File "/home/ejakupov/.conda/envs/mda2/lib/python3.8/site-packages/h5py-2.9.0-py3.8-linux-x86_64.egg/h5py/_hl/dataset.py", line 562, in __getitem__
    arr = numpy.ndarray(mshape, new_dtype, order='C')
MemoryError: Unable to allocate 113. GiB for an array with shape (90100, 111815, 3) and data type float32
Traceback (most recent call last):
  File "/scratch/ejakupov/Agave/benchmarks/in_memory_2/scripts/benchmark.py", line 208, in <module>
    times_array, rmsd_array = benchmark(topology, trajectory)
  File "/scratch/ejakupov/Agave/benchmarks/in_memory_2/scripts/benchmark.py", line 48, in benchmark
    u.transfer_to_memory(start=start, stop=stop, step=1)
  File "/home/ejakupov/mdanalysis/package/MDAnalysis/core/universe.py", line 605, in transfer_to_memory
    np.copyto(coordinates, group['position/value'][()])
  File "h5py/_objects.pyx", line 54, in h5py._objects.with_phil.wrapper
  File "h5py/_objects.pyx", line 55, in h5py._objects.with_phil.wrapper
  File "/home/ejakupov/.conda/envs/mda2/lib/python3.8/site-packages/h5py-2.9.0-py3.8-linux-x86_64.egg/h5py/_hl/dataset.py", line 562, in __getitem__
    arr = numpy.ndarray(mshape, new_dtype, order='C')
MemoryError: Unable to allocate 113. GiB for an array with shape (90100, 111815, 3) and data type float32
Traceback (most recent call last):
  File "/scratch/ejakupov/Agave/benchmarks/in_memory_2/scripts/benchmark.py", line 208, in <module>
    times_array, rmsd_array = benchmark(topology, trajectory)
  File "/scratch/ejakupov/Agave/benchmarks/in_memory_2/scripts/benchmark.py", line 48, in benchmark
    u.transfer_to_memory(start=start, stop=stop, step=1)
  File "/home/ejakupov/mdanalysis/package/MDAnalysis/core/universe.py", line 593, in transfer_to_memory
    coordinates = np.zeros((n_frames, n_atoms, 3), dtype=np.float32)
MemoryError: Unable to allocate 2.01 GiB for an array with shape (1609, 111815, 3) and data type float32
Traceback (most recent call last):
  File "/scratch/ejakupov/Agave/benchmarks/in_memory_2/scripts/benchmark.py", line 208, in <module>
    times_array, rmsd_array = benchmark(topology, trajectory)
  File "/scratch/ejakupov/Agave/benchmarks/in_memory_2/scripts/benchmark.py", line 48, in benchmark
    u.transfer_to_memory(start=start, stop=stop, step=1)
  File "/home/ejakupov/mdanalysis/package/MDAnalysis/core/universe.py", line 605, in transfer_to_memory
    np.copyto(coordinates, group['position/value'][()])
  File "h5py/_objects.pyx", line 54, in h5py._objects.with_phil.wrapper
  File "h5py/_objects.pyx", line 55, in h5py._objects.with_phil.wrapper
  File "/home/ejakupov/.conda/envs/mda2/lib/python3.8/site-packages/h5py-2.9.0-py3.8-linux-x86_64.egg/h5py/_hl/dataset.py", line 562, in __getitem__
    arr = numpy.ndarray(mshape, new_dtype, order='C')
MemoryError: Unable to allocate 113. GiB for an array with shape (90100, 111815, 3) and data type float32
Traceback (most recent call last):
  File "/scratch/ejakupov/Agave/benchmarks/in_memory_2/scripts/benchmark.py", line 208, in <module>
    times_array, rmsd_array = benchmark(topology, trajectory)
  File "/scratch/ejakupov/Agave/benchmarks/in_memory_2/scripts/benchmark.py", line 48, in benchmark
    u.transfer_to_memory(start=start, stop=stop, step=1)
  File "/home/ejakupov/mdanalysis/package/MDAnalysis/core/universe.py", line 605, in transfer_to_memory
    np.copyto(coordinates, group['position/value'][()])
  File "h5py/_objects.pyx", line 54, in h5py._objects.with_phil.wrapper
  File "h5py/_objects.pyx", line 55, in h5py._objects.with_phil.wrapper
  File "/home/ejakupov/.conda/envs/mda2/lib/python3.8/site-packages/h5py-2.9.0-py3.8-linux-x86_64.egg/h5py/_hl/dataset.py", line 562, in __getitem__
    arr = numpy.ndarray(mshape, new_dtype, order='C')
MemoryError: Unable to allocate 113. GiB for an array with shape (90100, 111815, 3) and data type float32
Traceback (most recent call last):
  File "/scratch/ejakupov/Agave/benchmarks/in_memory_2/scripts/benchmark.py", line 208, in <module>
    times_array, rmsd_array = benchmark(topology, trajectory)
  File "/scratch/ejakupov/Agave/benchmarks/in_memory_2/scripts/benchmark.py", line 48, in benchmark
    u.transfer_to_memory(start=start, stop=stop, step=1)
  File "/home/ejakupov/mdanalysis/package/MDAnalysis/core/universe.py", line 605, in transfer_to_memory
    np.copyto(coordinates, group['position/value'][()])
  File "h5py/_objects.pyx", line 54, in h5py._objects.with_phil.wrapper
  File "h5py/_objects.pyx", line 55, in h5py._objects.with_phil.wrapper
  File "/home/ejakupov/.conda/envs/mda2/lib/python3.8/site-packages/h5py-2.9.0-py3.8-linux-x86_64.egg/h5py/_hl/dataset.py", line 562, in __getitem__
    arr = numpy.ndarray(mshape, new_dtype, order='C')
MemoryError: Unable to allocate 113. GiB for an array with shape (90100, 111815, 3) and data type float32
Traceback (most recent call last):
  File "/scratch/ejakupov/Agave/benchmarks/in_memory_2/scripts/benchmark.py", line 208, in <module>
    times_array, rmsd_array = benchmark(topology, trajectory)
  File "/scratch/ejakupov/Agave/benchmarks/in_memory_2/scripts/benchmark.py", line 48, in benchmark
    u.transfer_to_memory(start=start, stop=stop, step=1)
  File "/home/ejakupov/mdanalysis/package/MDAnalysis/core/universe.py", line 605, in transfer_to_memory
    np.copyto(coordinates, group['position/value'][()])
  File "h5py/_objects.pyx", line 54, in h5py._objects.with_phil.wrapper
  File "h5py/_objects.pyx", line 55, in h5py._objects.with_phil.wrapper
  File "/home/ejakupov/.conda/envs/mda2/lib/python3.8/site-packages/h5py-2.9.0-py3.8-linux-x86_64.egg/h5py/_hl/dataset.py", line 562, in __getitem__
    arr = numpy.ndarray(mshape, new_dtype, order='C')
MemoryError: Unable to allocate 113. GiB for an array with shape (90100, 111815, 3) and data type float32
Traceback (most recent call last):
  File "/scratch/ejakupov/Agave/benchmarks/in_memory_2/scripts/benchmark.py", line 208, in <module>
    times_array, rmsd_array = benchmark(topology, trajectory)
  File "/scratch/ejakupov/Agave/benchmarks/in_memory_2/scripts/benchmark.py", line 48, in benchmark
    u.transfer_to_memory(start=start, stop=stop, step=1)
  File "/home/ejakupov/mdanalysis/package/MDAnalysis/core/universe.py", line 605, in transfer_to_memory
    np.copyto(coordinates, group['position/value'][()])
  File "h5py/_objects.pyx", line 54, in h5py._objects.with_phil.wrapper
  File "h5py/_objects.pyx", line 55, in h5py._objects.with_phil.wrapper
  File "/home/ejakupov/.conda/envs/mda2/lib/python3.8/site-packages/h5py-2.9.0-py3.8-linux-x86_64.egg/h5py/_hl/dataset.py", line 562, in __getitem__
    arr = numpy.ndarray(mshape, new_dtype, order='C')
MemoryError: Unable to allocate 113. GiB for an array with shape (90100, 111815, 3) and data type float32
Traceback (most recent call last):
  File "/scratch/ejakupov/Agave/benchmarks/in_memory_2/scripts/benchmark.py", line 208, in <module>
    times_array, rmsd_array = benchmark(topology, trajectory)
  File "/scratch/ejakupov/Agave/benchmarks/in_memory_2/scripts/benchmark.py", line 48, in benchmark
    u.transfer_to_memory(start=start, stop=stop, step=1)
  File "/home/ejakupov/mdanalysis/package/MDAnalysis/core/universe.py", line 605, in transfer_to_memory
    np.copyto(coordinates, group['position/value'][()])
  File "h5py/_objects.pyx", line 54, in h5py._objects.with_phil.wrapper
  File "h5py/_objects.pyx", line 55, in h5py._objects.with_phil.wrapper
  File "/home/ejakupov/.conda/envs/mda2/lib/python3.8/site-packages/h5py-2.9.0-py3.8-linux-x86_64.egg/h5py/_hl/dataset.py", line 562, in __getitem__
    arr = numpy.ndarray(mshape, new_dtype, order='C')
MemoryError: Unable to allocate 113. GiB for an array with shape (90100, 111815, 3) and data type float32
Traceback (most recent call last):
  File "/scratch/ejakupov/Agave/benchmarks/in_memory_2/scripts/benchmark.py", line 208, in <module>
    times_array, rmsd_array = benchmark(topology, trajectory)
  File "/scratch/ejakupov/Agave/benchmarks/in_memory_2/scripts/benchmark.py", line 48, in benchmark
    u.transfer_to_memory(start=start, stop=stop, step=1)
  File "/home/ejakupov/mdanalysis/package/MDAnalysis/core/universe.py", line 593, in transfer_to_memory
    coordinates = np.zeros((n_frames, n_atoms, 3), dtype=np.float32)
MemoryError: Unable to allocate 2.01 GiB for an array with shape (1609, 111815, 3) and data type float32
Traceback (most recent call last):
  File "/scratch/ejakupov/Agave/benchmarks/in_memory_2/scripts/benchmark.py", line 208, in <module>
    times_array, rmsd_array = benchmark(topology, trajectory)
  File "/scratch/ejakupov/Agave/benchmarks/in_memory_2/scripts/benchmark.py", line 48, in benchmark
    u.transfer_to_memory(start=start, stop=stop, step=1)
  File "/home/ejakupov/mdanalysis/package/MDAnalysis/core/universe.py", line 593, in transfer_to_memory
    coordinates = np.zeros((n_frames, n_atoms, 3), dtype=np.float32)
MemoryError: Unable to allocate 2.01 GiB for an array with shape (1609, 111815, 3) and data type float32
Traceback (most recent call last):
  File "/scratch/ejakupov/Agave/benchmarks/in_memory_2/scripts/benchmark.py", line 208, in <module>
    times_array, rmsd_array = benchmark(topology, trajectory)
  File "/scratch/ejakupov/Agave/benchmarks/in_memory_2/scripts/benchmark.py", line 48, in benchmark
    u.transfer_to_memory(start=start, stop=stop, step=1)
  File "/home/ejakupov/mdanalysis/package/MDAnalysis/core/universe.py", line 593, in transfer_to_memory
    coordinates = np.zeros((n_frames, n_atoms, 3), dtype=np.float32)
MemoryError: Unable to allocate 2.01 GiB for an array with shape (1609, 111815, 3) and data type float32
Traceback (most recent call last):
  File "/scratch/ejakupov/Agave/benchmarks/in_memory_2/scripts/benchmark.py", line 208, in <module>
    times_array, rmsd_array = benchmark(topology, trajectory)
  File "/scratch/ejakupov/Agave/benchmarks/in_memory_2/scripts/benchmark.py", line 48, in benchmark
    u.transfer_to_memory(start=start, stop=stop, step=1)
  File "/home/ejakupov/mdanalysis/package/MDAnalysis/core/universe.py", line 593, in transfer_to_memory
    coordinates = np.zeros((n_frames, n_atoms, 3), dtype=np.float32)
MemoryError: Unable to allocate 2.01 GiB for an array with shape (1609, 111815, 3) and data type float32
Traceback (most recent call last):
  File "/scratch/ejakupov/Agave/benchmarks/in_memory_2/scripts/benchmark.py", line 208, in <module>
    times_array, rmsd_array = benchmark(topology, trajectory)
  File "/scratch/ejakupov/Agave/benchmarks/in_memory_2/scripts/benchmark.py", line 48, in benchmark
    u.transfer_to_memory(start=start, stop=stop, step=1)
  File "/home/ejakupov/mdanalysis/package/MDAnalysis/core/universe.py", line 605, in transfer_to_memory
    np.copyto(coordinates, group['position/value'][()])
  File "h5py/_objects.pyx", line 54, in h5py._objects.with_phil.wrapper
  File "h5py/_objects.pyx", line 55, in h5py._objects.with_phil.wrapper
  File "/home/ejakupov/.conda/envs/mda2/lib/python3.8/site-packages/h5py-2.9.0-py3.8-linux-x86_64.egg/h5py/_hl/dataset.py", line 562, in __getitem__
    arr = numpy.ndarray(mshape, new_dtype, order='C')
MemoryError: Unable to allocate 113. GiB for an array with shape (90100, 111815, 3) and data type float32
Traceback (most recent call last):
  File "/scratch/ejakupov/Agave/benchmarks/in_memory_2/scripts/benchmark.py", line 208, in <module>
    times_array, rmsd_array = benchmark(topology, trajectory)
  File "/scratch/ejakupov/Agave/benchmarks/in_memory_2/scripts/benchmark.py", line 48, in benchmark
    u.transfer_to_memory(start=start, stop=stop, step=1)
  File "/home/ejakupov/mdanalysis/package/MDAnalysis/core/universe.py", line 593, in transfer_to_memory
    coordinates = np.zeros((n_frames, n_atoms, 3), dtype=np.float32)
MemoryError: Unable to allocate 2.01 GiB for an array with shape (1609, 111815, 3) and data type float32
Traceback (most recent call last):
  File "/scratch/ejakupov/Agave/benchmarks/in_memory_2/scripts/benchmark.py", line 208, in <module>
    times_array, rmsd_array = benchmark(topology, trajectory)
  File "/scratch/ejakupov/Agave/benchmarks/in_memory_2/scripts/benchmark.py", line 48, in benchmark
    u.transfer_to_memory(start=start, stop=stop, step=1)
  File "/home/ejakupov/mdanalysis/package/MDAnalysis/core/universe.py", line 605, in transfer_to_memory
    np.copyto(coordinates, group['position/value'][()])
  File "h5py/_objects.pyx", line 54, in h5py._objects.with_phil.wrapper
  File "h5py/_objects.pyx", line 55, in h5py._objects.with_phil.wrapper
  File "/home/ejakupov/.conda/envs/mda2/lib/python3.8/site-packages/h5py-2.9.0-py3.8-linux-x86_64.egg/h5py/_hl/dataset.py", line 562, in __getitem__
    arr = numpy.ndarray(mshape, new_dtype, order='C')
MemoryError: Unable to allocate 113. GiB for an array with shape (90100, 111815, 3) and data type float32
Traceback (most recent call last):
  File "/scratch/ejakupov/Agave/benchmarks/in_memory_2/scripts/benchmark.py", line 208, in <module>
    times_array, rmsd_array = benchmark(topology, trajectory)
  File "/scratch/ejakupov/Agave/benchmarks/in_memory_2/scripts/benchmark.py", line 48, in benchmark
    u.transfer_to_memory(start=start, stop=stop, step=1)
  File "/home/ejakupov/mdanalysis/package/MDAnalysis/core/universe.py", line 605, in transfer_to_memory
    np.copyto(coordinates, group['position/value'][()])
  File "h5py/_objects.pyx", line 54, in h5py._objects.with_phil.wrapper
  File "h5py/_objects.pyx", line 55, in h5py._objects.with_phil.wrapper
  File "/home/ejakupov/.conda/envs/mda2/lib/python3.8/site-packages/h5py-2.9.0-py3.8-linux-x86_64.egg/h5py/_hl/dataset.py", line 562, in __getitem__
    arr = numpy.ndarray(mshape, new_dtype, order='C')
MemoryError: Unable to allocate 113. GiB for an array with shape (90100, 111815, 3) and data type float32
Traceback (most recent call last):
  File "/scratch/ejakupov/Agave/benchmarks/in_memory_2/scripts/benchmark.py", line 208, in <module>
    times_array, rmsd_array = benchmark(topology, trajectory)
  File "/scratch/ejakupov/Agave/benchmarks/in_memory_2/scripts/benchmark.py", line 48, in benchmark
    u.transfer_to_memory(start=start, stop=stop, step=1)
  File "/home/ejakupov/mdanalysis/package/MDAnalysis/core/universe.py", line 605, in transfer_to_memory
    np.copyto(coordinates, group['position/value'][()])
  File "h5py/_objects.pyx", line 54, in h5py._objects.with_phil.wrapper
  File "h5py/_objects.pyx", line 55, in h5py._objects.with_phil.wrapper
  File "/home/ejakupov/.conda/envs/mda2/lib/python3.8/site-packages/h5py-2.9.0-py3.8-linux-x86_64.egg/h5py/_hl/dataset.py", line 562, in __getitem__
    arr = numpy.ndarray(mshape, new_dtype, order='C')
MemoryError: Unable to allocate 113. GiB for an array with shape (90100, 111815, 3) and data type float32
Traceback (most recent call last):
  File "/scratch/ejakupov/Agave/benchmarks/in_memory_2/scripts/benchmark.py", line 208, in <module>
    times_array, rmsd_array = benchmark(topology, trajectory)
  File "/scratch/ejakupov/Agave/benchmarks/in_memory_2/scripts/benchmark.py", line 48, in benchmark
    u.transfer_to_memory(start=start, stop=stop, step=1)
  File "/home/ejakupov/mdanalysis/package/MDAnalysis/core/universe.py", line 593, in transfer_to_memory
    coordinates = np.zeros((n_frames, n_atoms, 3), dtype=np.float32)
MemoryError: Unable to allocate 2.01 GiB for an array with shape (1609, 111815, 3) and data type float32
Traceback (most recent call last):
  File "/scratch/ejakupov/Agave/benchmarks/in_memory_2/scripts/benchmark.py", line 208, in <module>
    times_array, rmsd_array = benchmark(topology, trajectory)
  File "/scratch/ejakupov/Agave/benchmarks/in_memory_2/scripts/benchmark.py", line 48, in benchmark
    u.transfer_to_memory(start=start, stop=stop, step=1)
  File "/home/ejakupov/mdanalysis/package/MDAnalysis/core/universe.py", line 605, in transfer_to_memory
    np.copyto(coordinates, group['position/value'][()])
  File "h5py/_objects.pyx", line 54, in h5py._objects.with_phil.wrapper
  File "h5py/_objects.pyx", line 55, in h5py._objects.with_phil.wrapper
  File "/home/ejakupov/.conda/envs/mda2/lib/python3.8/site-packages/h5py-2.9.0-py3.8-linux-x86_64.egg/h5py/_hl/dataset.py", line 562, in __getitem__
    arr = numpy.ndarray(mshape, new_dtype, order='C')
MemoryError: Unable to allocate 113. GiB for an array with shape (90100, 111815, 3) and data type float32
Traceback (most recent call last):
  File "/scratch/ejakupov/Agave/benchmarks/in_memory_2/scripts/benchmark.py", line 208, in <module>
    times_array, rmsd_array = benchmark(topology, trajectory)
  File "/scratch/ejakupov/Agave/benchmarks/in_memory_2/scripts/benchmark.py", line 48, in benchmark
    u.transfer_to_memory(start=start, stop=stop, step=1)
  File "/home/ejakupov/mdanalysis/package/MDAnalysis/core/universe.py", line 593, in transfer_to_memory
    coordinates = np.zeros((n_frames, n_atoms, 3), dtype=np.float32)
MemoryError: Unable to allocate 2.01 GiB for an array with shape (1609, 111815, 3) and data type float32
Traceback (most recent call last):
  File "/scratch/ejakupov/Agave/benchmarks/in_memory_2/scripts/benchmark.py", line 208, in <module>
    times_array, rmsd_array = benchmark(topology, trajectory)
  File "/scratch/ejakupov/Agave/benchmarks/in_memory_2/scripts/benchmark.py", line 48, in benchmark
    u.transfer_to_memory(start=start, stop=stop, step=1)
  File "/home/ejakupov/mdanalysis/package/MDAnalysis/core/universe.py", line 605, in transfer_to_memory
    np.copyto(coordinates, group['position/value'][()])
  File "h5py/_objects.pyx", line 54, in h5py._objects.with_phil.wrapper
  File "h5py/_objects.pyx", line 55, in h5py._objects.with_phil.wrapper
  File "/home/ejakupov/.conda/envs/mda2/lib/python3.8/site-packages/h5py-2.9.0-py3.8-linux-x86_64.egg/h5py/_hl/dataset.py", line 562, in __getitem__
    arr = numpy.ndarray(mshape, new_dtype, order='C')
MemoryError: Unable to allocate 113. GiB for an array with shape (90100, 111815, 3) and data type float32
Traceback (most recent call last):
  File "/scratch/ejakupov/Agave/benchmarks/in_memory_2/scripts/benchmark.py", line 208, in <module>
    times_array, rmsd_array = benchmark(topology, trajectory)
  File "/scratch/ejakupov/Agave/benchmarks/in_memory_2/scripts/benchmark.py", line 48, in benchmark
    u.transfer_to_memory(start=start, stop=stop, step=1)
  File "/home/ejakupov/mdanalysis/package/MDAnalysis/core/universe.py", line 605, in transfer_to_memory
    np.copyto(coordinates, group['position/value'][()])
  File "h5py/_objects.pyx", line 54, in h5py._objects.with_phil.wrapper
  File "h5py/_objects.pyx", line 55, in h5py._objects.with_phil.wrapper
  File "/home/ejakupov/.conda/envs/mda2/lib/python3.8/site-packages/h5py-2.9.0-py3.8-linux-x86_64.egg/h5py/_hl/dataset.py", line 562, in __getitem__
    arr = numpy.ndarray(mshape, new_dtype, order='C')
MemoryError: Unable to allocate 113. GiB for an array with shape (90100, 111815, 3) and data type float32
Traceback (most recent call last):
  File "/scratch/ejakupov/Agave/benchmarks/in_memory_2/scripts/benchmark.py", line 208, in <module>
    times_array, rmsd_array = benchmark(topology, trajectory)
  File "/scratch/ejakupov/Agave/benchmarks/in_memory_2/scripts/benchmark.py", line 48, in benchmark
    u.transfer_to_memory(start=start, stop=stop, step=1)
  File "/home/ejakupov/mdanalysis/package/MDAnalysis/core/universe.py", line 605, in transfer_to_memory
    np.copyto(coordinates, group['position/value'][()])
  File "h5py/_objects.pyx", line 54, in h5py._objects.with_phil.wrapper
  File "h5py/_objects.pyx", line 55, in h5py._objects.with_phil.wrapper
  File "/home/ejakupov/.conda/envs/mda2/lib/python3.8/site-packages/h5py-2.9.0-py3.8-linux-x86_64.egg/h5py/_hl/dataset.py", line 562, in __getitem__
    arr = numpy.ndarray(mshape, new_dtype, order='C')
MemoryError: Unable to allocate 113. GiB for an array with shape (90100, 111815, 3) and data type float32
Traceback (most recent call last):
  File "/scratch/ejakupov/Agave/benchmarks/in_memory_2/scripts/benchmark.py", line 208, in <module>
    times_array, rmsd_array = benchmark(topology, trajectory)
  File "/scratch/ejakupov/Agave/benchmarks/in_memory_2/scripts/benchmark.py", line 48, in benchmark
    u.transfer_to_memory(start=start, stop=stop, step=1)
  File "/home/ejakupov/mdanalysis/package/MDAnalysis/core/universe.py", line 593, in transfer_to_memory
    coordinates = np.zeros((n_frames, n_atoms, 3), dtype=np.float32)
MemoryError: Unable to allocate 2.01 GiB for an array with shape (1609, 111815, 3) and data type float32
Traceback (most recent call last):
  File "/scratch/ejakupov/Agave/benchmarks/in_memory_2/scripts/benchmark.py", line 208, in <module>
    times_array, rmsd_array = benchmark(topology, trajectory)
  File "/scratch/ejakupov/Agave/benchmarks/in_memory_2/scripts/benchmark.py", line 48, in benchmark
    u.transfer_to_memory(start=start, stop=stop, step=1)
  File "/home/ejakupov/mdanalysis/package/MDAnalysis/core/universe.py", line 593, in transfer_to_memory
    coordinates = np.zeros((n_frames, n_atoms, 3), dtype=np.float32)
MemoryError: Unable to allocate 2.01 GiB for an array with shape (1609, 111815, 3) and data type float32
Traceback (most recent call last):
  File "/scratch/ejakupov/Agave/benchmarks/in_memory_2/scripts/benchmark.py", line 208, in <module>
    times_array, rmsd_array = benchmark(topology, trajectory)
  File "/scratch/ejakupov/Agave/benchmarks/in_memory_2/scripts/benchmark.py", line 48, in benchmark
    u.transfer_to_memory(start=start, stop=stop, step=1)
  File "/home/ejakupov/mdanalysis/package/MDAnalysis/core/universe.py", line 605, in transfer_to_memory
    np.copyto(coordinates, group['position/value'][()])
  File "h5py/_objects.pyx", line 54, in h5py._objects.with_phil.wrapper
  File "h5py/_objects.pyx", line 55, in h5py._objects.with_phil.wrapper
  File "/home/ejakupov/.conda/envs/mda2/lib/python3.8/site-packages/h5py-2.9.0-py3.8-linux-x86_64.egg/h5py/_hl/dataset.py", line 562, in __getitem__
    arr = numpy.ndarray(mshape, new_dtype, order='C')
MemoryError: Unable to allocate 113. GiB for an array with shape (90100, 111815, 3) and data type float32
Traceback (most recent call last):
  File "/scratch/ejakupov/Agave/benchmarks/in_memory_2/scripts/benchmark.py", line 208, in <module>
    times_array, rmsd_array = benchmark(topology, trajectory)
  File "/scratch/ejakupov/Agave/benchmarks/in_memory_2/scripts/benchmark.py", line 48, in benchmark
    u.transfer_to_memory(start=start, stop=stop, step=1)
  File "/home/ejakupov/mdanalysis/package/MDAnalysis/core/universe.py", line 605, in transfer_to_memory
    np.copyto(coordinates, group['position/value'][()])
  File "h5py/_objects.pyx", line 54, in h5py._objects.with_phil.wrapper
  File "h5py/_objects.pyx", line 55, in h5py._objects.with_phil.wrapper
  File "/home/ejakupov/.conda/envs/mda2/lib/python3.8/site-packages/h5py-2.9.0-py3.8-linux-x86_64.egg/h5py/_hl/dataset.py", line 562, in __getitem__
    arr = numpy.ndarray(mshape, new_dtype, order='C')
MemoryError: Unable to allocate 113. GiB for an array with shape (90100, 111815, 3) and data type float32
Traceback (most recent call last):
  File "/scratch/ejakupov/Agave/benchmarks/in_memory_2/scripts/benchmark.py", line 208, in <module>
    times_array, rmsd_array = benchmark(topology, trajectory)
  File "/scratch/ejakupov/Agave/benchmarks/in_memory_2/scripts/benchmark.py", line 48, in benchmark
    u.transfer_to_memory(start=start, stop=stop, step=1)
  File "/home/ejakupov/mdanalysis/package/MDAnalysis/core/universe.py", line 605, in transfer_to_memory
    np.copyto(coordinates, group['position/value'][()])
  File "h5py/_objects.pyx", line 54, in h5py._objects.with_phil.wrapper
  File "h5py/_objects.pyx", line 55, in h5py._objects.with_phil.wrapper
  File "/home/ejakupov/.conda/envs/mda2/lib/python3.8/site-packages/h5py-2.9.0-py3.8-linux-x86_64.egg/h5py/_hl/dataset.py", line 562, in __getitem__
    arr = numpy.ndarray(mshape, new_dtype, order='C')
MemoryError: Unable to allocate 113. GiB for an array with shape (90100, 111815, 3) and data type float32
Traceback (most recent call last):
  File "/scratch/ejakupov/Agave/benchmarks/in_memory_2/scripts/benchmark.py", line 208, in <module>
    times_array, rmsd_array = benchmark(topology, trajectory)
  File "/scratch/ejakupov/Agave/benchmarks/in_memory_2/scripts/benchmark.py", line 48, in benchmark
    u.transfer_to_memory(start=start, stop=stop, step=1)
  File "/home/ejakupov/mdanalysis/package/MDAnalysis/core/universe.py", line 605, in transfer_to_memory
    np.copyto(coordinates, group['position/value'][()])
  File "h5py/_objects.pyx", line 54, in h5py._objects.with_phil.wrapper
  File "h5py/_objects.pyx", line 55, in h5py._objects.with_phil.wrapper
  File "/home/ejakupov/.conda/envs/mda2/lib/python3.8/site-packages/h5py-2.9.0-py3.8-linux-x86_64.egg/h5py/_hl/dataset.py", line 562, in __getitem__
    arr = numpy.ndarray(mshape, new_dtype, order='C')
MemoryError: Unable to allocate 113. GiB for an array with shape (90100, 111815, 3) and data type float32
Traceback (most recent call last):
  File "/scratch/ejakupov/Agave/benchmarks/in_memory_2/scripts/benchmark.py", line 208, in <module>
    times_array, rmsd_array = benchmark(topology, trajectory)
  File "/scratch/ejakupov/Agave/benchmarks/in_memory_2/scripts/benchmark.py", line 48, in benchmark
    u.transfer_to_memory(start=start, stop=stop, step=1)
  File "/home/ejakupov/mdanalysis/package/MDAnalysis/core/universe.py", line 593, in transfer_to_memory
    coordinates = np.zeros((n_frames, n_atoms, 3), dtype=np.float32)
MemoryError: Unable to allocate 2.01 GiB for an array with shape (1609, 111815, 3) and data type float32
Traceback (most recent call last):
  File "/scratch/ejakupov/Agave/benchmarks/in_memory_2/scripts/benchmark.py", line 208, in <module>
    times_array, rmsd_array = benchmark(topology, trajectory)
  File "/scratch/ejakupov/Agave/benchmarks/in_memory_2/scripts/benchmark.py", line 48, in benchmark
    u.transfer_to_memory(start=start, stop=stop, step=1)
  File "/home/ejakupov/mdanalysis/package/MDAnalysis/core/universe.py", line 605, in transfer_to_memory
    np.copyto(coordinates, group['position/value'][()])
  File "h5py/_objects.pyx", line 54, in h5py._objects.with_phil.wrapper
  File "h5py/_objects.pyx", line 55, in h5py._objects.with_phil.wrapper
  File "/home/ejakupov/.conda/envs/mda2/lib/python3.8/site-packages/h5py-2.9.0-py3.8-linux-x86_64.egg/h5py/_hl/dataset.py", line 562, in __getitem__
    arr = numpy.ndarray(mshape, new_dtype, order='C')
MemoryError: Unable to allocate 113. GiB for an array with shape (90100, 111815, 3) and data type float32
Traceback (most recent call last):
  File "/scratch/ejakupov/Agave/benchmarks/in_memory_2/scripts/benchmark.py", line 208, in <module>
    times_array, rmsd_array = benchmark(topology, trajectory)
  File "/scratch/ejakupov/Agave/benchmarks/in_memory_2/scripts/benchmark.py", line 48, in benchmark
    u.transfer_to_memory(start=start, stop=stop, step=1)
  File "/home/ejakupov/mdanalysis/package/MDAnalysis/core/universe.py", line 605, in transfer_to_memory
    np.copyto(coordinates, group['position/value'][()])
  File "h5py/_objects.pyx", line 54, in h5py._objects.with_phil.wrapper
  File "h5py/_objects.pyx", line 55, in h5py._objects.with_phil.wrapper
  File "/home/ejakupov/.conda/envs/mda2/lib/python3.8/site-packages/h5py-2.9.0-py3.8-linux-x86_64.egg/h5py/_hl/dataset.py", line 562, in __getitem__
    arr = numpy.ndarray(mshape, new_dtype, order='C')
MemoryError: Unable to allocate 113. GiB for an array with shape (90100, 111815, 3) and data type float32
Traceback (most recent call last):
  File "/scratch/ejakupov/Agave/benchmarks/in_memory_2/scripts/benchmark.py", line 208, in <module>
    times_array, rmsd_array = benchmark(topology, trajectory)
  File "/scratch/ejakupov/Agave/benchmarks/in_memory_2/scripts/benchmark.py", line 48, in benchmark
    u.transfer_to_memory(start=start, stop=stop, step=1)
  File "/home/ejakupov/mdanalysis/package/MDAnalysis/core/universe.py", line 593, in transfer_to_memory
    coordinates = np.zeros((n_frames, n_atoms, 3), dtype=np.float32)
MemoryError: Unable to allocate 2.01 GiB for an array with shape (1609, 111815, 3) and data type float32
Traceback (most recent call last):
  File "/scratch/ejakupov/Agave/benchmarks/in_memory_2/scripts/benchmark.py", line 208, in <module>
    times_array, rmsd_array = benchmark(topology, trajectory)
  File "/scratch/ejakupov/Agave/benchmarks/in_memory_2/scripts/benchmark.py", line 48, in benchmark
    u.transfer_to_memory(start=start, stop=stop, step=1)
  File "/home/ejakupov/mdanalysis/package/MDAnalysis/core/universe.py", line 605, in transfer_to_memory
    np.copyto(coordinates, group['position/value'][()])
  File "h5py/_objects.pyx", line 54, in h5py._objects.with_phil.wrapper
  File "h5py/_objects.pyx", line 55, in h5py._objects.with_phil.wrapper
  File "/home/ejakupov/.conda/envs/mda2/lib/python3.8/site-packages/h5py-2.9.0-py3.8-linux-x86_64.egg/h5py/_hl/dataset.py", line 562, in __getitem__
    arr = numpy.ndarray(mshape, new_dtype, order='C')
MemoryError: Unable to allocate 113. GiB for an array with shape (90100, 111815, 3) and data type float32
Traceback (most recent call last):
  File "/scratch/ejakupov/Agave/benchmarks/in_memory_2/scripts/benchmark.py", line 208, in <module>
    times_array, rmsd_array = benchmark(topology, trajectory)
  File "/scratch/ejakupov/Agave/benchmarks/in_memory_2/scripts/benchmark.py", line 48, in benchmark
    u.transfer_to_memory(start=start, stop=stop, step=1)
  File "/home/ejakupov/mdanalysis/package/MDAnalysis/core/universe.py", line 605, in transfer_to_memory
    np.copyto(coordinates, group['position/value'][()])
  File "h5py/_objects.pyx", line 54, in h5py._objects.with_phil.wrapper
  File "h5py/_objects.pyx", line 55, in h5py._objects.with_phil.wrapper
  File "/home/ejakupov/.conda/envs/mda2/lib/python3.8/site-packages/h5py-2.9.0-py3.8-linux-x86_64.egg/h5py/_hl/dataset.py", line 562, in __getitem__
    arr = numpy.ndarray(mshape, new_dtype, order='C')
MemoryError: Unable to allocate 113. GiB for an array with shape (90100, 111815, 3) and data type float32
Traceback (most recent call last):
  File "/scratch/ejakupov/Agave/benchmarks/in_memory_2/scripts/benchmark.py", line 208, in <module>
    times_array, rmsd_array = benchmark(topology, trajectory)
  File "/scratch/ejakupov/Agave/benchmarks/in_memory_2/scripts/benchmark.py", line 48, in benchmark
    u.transfer_to_memory(start=start, stop=stop, step=1)
  File "/home/ejakupov/mdanalysis/package/MDAnalysis/core/universe.py", line 605, in transfer_to_memory
    np.copyto(coordinates, group['position/value'][()])
  File "h5py/_objects.pyx", line 54, in h5py._objects.with_phil.wrapper
  File "h5py/_objects.pyx", line 55, in h5py._objects.with_phil.wrapper
  File "/home/ejakupov/.conda/envs/mda2/lib/python3.8/site-packages/h5py-2.9.0-py3.8-linux-x86_64.egg/h5py/_hl/dataset.py", line 562, in __getitem__
    arr = numpy.ndarray(mshape, new_dtype, order='C')
MemoryError: Unable to allocate 113. GiB for an array with shape (90100, 111815, 3) and data type float32
Traceback (most recent call last):
  File "/scratch/ejakupov/Agave/benchmarks/in_memory_2/scripts/benchmark.py", line 208, in <module>
    times_array, rmsd_array = benchmark(topology, trajectory)
  File "/scratch/ejakupov/Agave/benchmarks/in_memory_2/scripts/benchmark.py", line 48, in benchmark
    u.transfer_to_memory(start=start, stop=stop, step=1)
  File "/home/ejakupov/mdanalysis/package/MDAnalysis/core/universe.py", line 593, in transfer_to_memory
    coordinates = np.zeros((n_frames, n_atoms, 3), dtype=np.float32)
MemoryError: Unable to allocate 2.01 GiB for an array with shape (1609, 111815, 3) and data type float32
Traceback (most recent call last):
  File "/scratch/ejakupov/Agave/benchmarks/in_memory_2/scripts/benchmark.py", line 208, in <module>
    times_array, rmsd_array = benchmark(topology, trajectory)
  File "/scratch/ejakupov/Agave/benchmarks/in_memory_2/scripts/benchmark.py", line 48, in benchmark
    u.transfer_to_memory(start=start, stop=stop, step=1)
  File "/home/ejakupov/mdanalysis/package/MDAnalysis/core/universe.py", line 605, in transfer_to_memory
    np.copyto(coordinates, group['position/value'][()])
  File "h5py/_objects.pyx", line 54, in h5py._objects.with_phil.wrapper
  File "h5py/_objects.pyx", line 55, in h5py._objects.with_phil.wrapper
  File "/home/ejakupov/.conda/envs/mda2/lib/python3.8/site-packages/h5py-2.9.0-py3.8-linux-x86_64.egg/h5py/_hl/dataset.py", line 573, in __getitem__
    self.id.read(mspace, fspace, arr, mtype, dxpl=self._dxpl)
  File "h5py/_objects.pyx", line 54, in h5py._objects.with_phil.wrapper
  File "h5py/_objects.pyx", line 55, in h5py._objects.with_phil.wrapper
  File "h5py/h5d.pyx", line 181, in h5py.h5d.DatasetID.read
  File "h5py/_proxy.pyx", line 130, in h5py._proxy.dset_rw
  File "h5py/_proxy.pyx", line 84, in h5py._proxy.H5PY_H5Dread
OSError: Can't read data (memory allocation failed for chunk)
Exception ignored in: <function ReaderBase.__del__ at 0x2b8f2fd68820>
Traceback (most recent call last):
  File "/home/ejakupov/mdanalysis/package/MDAnalysis/coordinates/base.py", line 2161, in __del__
  File "/home/ejakupov/mdanalysis/package/MDAnalysis/coordinates/H5MD.py", line 718, in close
  File "/home/ejakupov/.conda/envs/mda2/lib/python3.8/site-packages/h5py-2.9.0-py3.8-linux-x86_64.egg/h5py/_hl/files.py", line 412, in close
  File "h5py/_objects.pyx", line 54, in h5py._objects.with_phil.wrapper
  File "h5py/_objects.pyx", line 55, in h5py._objects.with_phil.wrapper
  File "h5py/h5f.pyx", line 264, in h5py.h5f.get_obj_ids
  File "h5py/h5i.pyx", line 43, in h5py.h5i.wrap_identifier
ImportError: sys.meta_path is None, Python is likely shutting down
Exception ignored in: <function ReaderBase.__del__ at 0x2b579ab03820>
Traceback (most recent call last):
  File "/home/ejakupov/mdanalysis/package/MDAnalysis/coordinates/base.py", line 2161, in __del__
  File "/home/ejakupov/mdanalysis/package/MDAnalysis/coordinates/H5MD.py", line 718, in close
  File "/home/ejakupov/.conda/envs/mda2/lib/python3.8/site-packages/h5py-2.9.0-py3.8-linux-x86_64.egg/h5py/_hl/files.py", line 412, in close
  File "h5py/_objects.pyx", line 54, in h5py._objects.with_phil.wrapper
  File "h5py/_objects.pyx", line 55, in h5py._objects.with_phil.wrapper
  File "h5py/h5f.pyx", line 264, in h5py.h5f.get_obj_ids
  File "h5py/h5i.pyx", line 43, in h5py.h5i.wrap_identifier
ImportError: sys.meta_path is None, Python is likely shutting down
Exception ignored in: <function ReaderBase.__del__ at 0x2aab69ac7820>
Traceback (most recent call last):
  File "/home/ejakupov/mdanalysis/package/MDAnalysis/coordinates/base.py", line 2161, in __del__
  File "/home/ejakupov/mdanalysis/package/MDAnalysis/coordinates/H5MD.py", line 718, in close
  File "/home/ejakupov/.conda/envs/mda2/lib/python3.8/site-packages/h5py-2.9.0-py3.8-linux-x86_64.egg/h5py/_hl/files.py", line 412, in close
  File "h5py/_objects.pyx", line 54, in h5py._objects.with_phil.wrapper
  File "h5py/_objects.pyx", line 55, in h5py._objects.with_phil.wrapper
  File "h5py/h5f.pyx", line 264, in h5py.h5f.get_obj_ids
  File "h5py/h5i.pyx", line 43, in h5py.h5i.wrap_identifier
ImportError: sys.meta_path is None, Python is likely shutting down
Exception ignored in: <function ReaderBase.__del__ at 0x2b7449539820>
Traceback (most recent call last):
  File "/home/ejakupov/mdanalysis/package/MDAnalysis/coordinates/base.py", line 2161, in __del__
  File "/home/ejakupov/mdanalysis/package/MDAnalysis/coordinates/H5MD.py", line 718, in close
  File "/home/ejakupov/.conda/envs/mda2/lib/python3.8/site-packages/h5py-2.9.0-py3.8-linux-x86_64.egg/h5py/_hl/files.py", line 412, in close
  File "h5py/_objects.pyx", line 54, in h5py._objects.with_phil.wrapper
  File "h5py/_objects.pyx", line 55, in h5py._objects.with_phil.wrapper
  File "h5py/h5f.pyx", line 264, in h5py.h5f.get_obj_ids
  File "h5py/h5i.pyx", line 43, in h5py.h5i.wrap_identifier
ImportError: sys.meta_path is None, Python is likely shutting down
Exception ignored in: <function ReaderBase.__del__ at 0x2b36e9132820>
Traceback (most recent call last):
  File "/home/ejakupov/mdanalysis/package/MDAnalysis/coordinates/base.py", line 2161, in __del__
  File "/home/ejakupov/mdanalysis/package/MDAnalysis/coordinates/H5MD.py", line 718, in close
  File "/home/ejakupov/.conda/envs/mda2/lib/python3.8/site-packages/h5py-2.9.0-py3.8-linux-x86_64.egg/h5py/_hl/files.py", line 412, in close
  File "h5py/_objects.pyx", line 54, in h5py._objects.with_phil.wrapper
  File "h5py/_objects.pyx", line 55, in h5py._objects.with_phil.wrapper
  File "h5py/h5f.pyx", line 264, in h5py.h5f.get_obj_ids
  File "h5py/h5i.pyx", line 43, in h5py.h5i.wrap_identifier
ImportError: sys.meta_path is None, Python is likely shutting down
Exception ignored in: <function ReaderBase.__del__ at 0x2aca50b5d820>
Traceback (most recent call last):
  File "/home/ejakupov/mdanalysis/package/MDAnalysis/coordinates/base.py", line 2161, in __del__
  File "/home/ejakupov/mdanalysis/package/MDAnalysis/coordinates/H5MD.py", line 718, in close
  File "/home/ejakupov/.conda/envs/mda2/lib/python3.8/site-packages/h5py-2.9.0-py3.8-linux-x86_64.egg/h5py/_hl/files.py", line 412, in close
  File "h5py/_objects.pyx", line 54, in h5py._objects.with_phil.wrapper
  File "h5py/_objects.pyx", line 55, in h5py._objects.with_phil.wrapper
  File "h5py/h5f.pyx", line 264, in h5py.h5f.get_obj_ids
  File "h5py/h5i.pyx", line 43, in h5py.h5i.wrap_identifier
ImportError: sys.meta_path is None, Python is likely shutting down
Exception ignored in: <function ReaderBase.__del__ at 0x2b6a8a43c820>
Traceback (most recent call last):
  File "/home/ejakupov/mdanalysis/package/MDAnalysis/coordinates/base.py", line 2161, in __del__
  File "/home/ejakupov/mdanalysis/package/MDAnalysis/coordinates/H5MD.py", line 718, in close
  File "/home/ejakupov/.conda/envs/mda2/lib/python3.8/site-packages/h5py-2.9.0-py3.8-linux-x86_64.egg/h5py/_hl/files.py", line 412, in close
  File "h5py/_objects.pyx", line 54, in h5py._objects.with_phil.wrapper
  File "h5py/_objects.pyx", line 55, in h5py._objects.with_phil.wrapper
  File "h5py/h5f.pyx", line 264, in h5py.h5f.get_obj_ids
  File "h5py/h5i.pyx", line 43, in h5py.h5i.wrap_identifier
ImportError: sys.meta_path is None, Python is likely shutting down
Exception ignored in: <function ReaderBase.__del__ at 0x2ad3cae8d820>
Traceback (most recent call last):
  File "/home/ejakupov/mdanalysis/package/MDAnalysis/coordinates/base.py", line 2161, in __del__
  File "/home/ejakupov/mdanalysis/package/MDAnalysis/coordinates/H5MD.py", line 718, in close
  File "/home/ejakupov/.conda/envs/mda2/lib/python3.8/site-packages/h5py-2.9.0-py3.8-linux-x86_64.egg/h5py/_hl/files.py", line 412, in close
  File "h5py/_objects.pyx", line 54, in h5py._objects.with_phil.wrapper
  File "h5py/_objects.pyx", line 55, in h5py._objects.with_phil.wrapper
  File "h5py/h5f.pyx", line 264, in h5py.h5f.get_obj_ids
  File "h5py/h5i.pyx", line 43, in h5py.h5i.wrap_identifier
ImportError: sys.meta_path is None, Python is likely shutting down
Exception ignored in: <function ReaderBase.__del__ at 0x2b67b4042820>
Traceback (most recent call last):
  File "/home/ejakupov/mdanalysis/package/MDAnalysis/coordinates/base.py", line 2161, in __del__
  File "/home/ejakupov/mdanalysis/package/MDAnalysis/coordinates/H5MD.py", line 718, in close
  File "/home/ejakupov/.conda/envs/mda2/lib/python3.8/site-packages/h5py-2.9.0-py3.8-linux-x86_64.egg/h5py/_hl/files.py", line 412, in close
  File "h5py/_objects.pyx", line 54, in h5py._objects.with_phil.wrapper
  File "h5py/_objects.pyx", line 55, in h5py._objects.with_phil.wrapper
  File "h5py/h5f.pyx", line 264, in h5py.h5f.get_obj_ids
  File "h5py/h5i.pyx", line 43, in h5py.h5i.wrap_identifier
ImportError: sys.meta_path is None, Python is likely shutting down
Exception ignored in: <function ReaderBase.__del__ at 0x2ad289e46820>
Traceback (most recent call last):
  File "/home/ejakupov/mdanalysis/package/MDAnalysis/coordinates/base.py", line 2161, in __del__
  File "/home/ejakupov/mdanalysis/package/MDAnalysis/coordinates/H5MD.py", line 718, in close
  File "/home/ejakupov/.conda/envs/mda2/lib/python3.8/site-packages/h5py-2.9.0-py3.8-linux-x86_64.egg/h5py/_hl/files.py", line 412, in close
  File "h5py/_objects.pyx", line 54, in h5py._objects.with_phil.wrapper
  File "h5py/_objects.pyx", line 55, in h5py._objects.with_phil.wrapper
  File "h5py/h5f.pyx", line 264, in h5py.h5f.get_obj_ids
  File "h5py/h5i.pyx", line 43, in h5py.h5i.wrap_identifier
ImportError: sys.meta_path is None, Python is likely shutting down
Exception ignored in: <function ReaderBase.__del__ at 0x2b275f706820>
Traceback (most recent call last):
  File "/home/ejakupov/mdanalysis/package/MDAnalysis/coordinates/base.py", line 2161, in __del__
  File "/home/ejakupov/mdanalysis/package/MDAnalysis/coordinates/H5MD.py", line 718, in close
  File "/home/ejakupov/.conda/envs/mda2/lib/python3.8/site-packages/h5py-2.9.0-py3.8-linux-x86_64.egg/h5py/_hl/files.py", line 412, in close
  File "h5py/_objects.pyx", line 54, in h5py._objects.with_phil.wrapper
  File "h5py/_objects.pyx", line 55, in h5py._objects.with_phil.wrapper
  File "h5py/h5f.pyx", line 264, in h5py.h5f.get_obj_ids
  File "h5py/h5i.pyx", line 43, in h5py.h5i.wrap_identifier
ImportError: sys.meta_path is None, Python is likely shutting down
Exception ignored in: <function ReaderBase.__del__ at 0x2b988e6d3820>
Traceback (most recent call last):
  File "/home/ejakupov/mdanalysis/package/MDAnalysis/coordinates/base.py", line 2161, in __del__
  File "/home/ejakupov/mdanalysis/package/MDAnalysis/coordinates/H5MD.py", line 718, in close
  File "/home/ejakupov/.conda/envs/mda2/lib/python3.8/site-packages/h5py-2.9.0-py3.8-linux-x86_64.egg/h5py/_hl/files.py", line 412, in close
  File "h5py/_objects.pyx", line 54, in h5py._objects.with_phil.wrapper
  File "h5py/_objects.pyx", line 55, in h5py._objects.with_phil.wrapper
  File "h5py/h5f.pyx", line 264, in h5py.h5f.get_obj_ids
  File "h5py/h5i.pyx", line 43, in h5py.h5i.wrap_identifier
ImportError: sys.meta_path is None, Python is likely shutting down
Exception ignored in: <function ReaderBase.__del__ at 0x2b264c6a4820>
Traceback (most recent call last):
  File "/home/ejakupov/mdanalysis/package/MDAnalysis/coordinates/base.py", line 2161, in __del__
  File "/home/ejakupov/mdanalysis/package/MDAnalysis/coordinates/H5MD.py", line 718, in close
  File "/home/ejakupov/.conda/envs/mda2/lib/python3.8/site-packages/h5py-2.9.0-py3.8-linux-x86_64.egg/h5py/_hl/files.py", line 412, in close
  File "h5py/_objects.pyx", line 54, in h5py._objects.with_phil.wrapper
  File "h5py/_objects.pyx", line 55, in h5py._objects.with_phil.wrapper
  File "h5py/h5f.pyx", line 264, in h5py.h5f.get_obj_ids
  File "h5py/h5i.pyx", line 43, in h5py.h5i.wrap_identifier
ImportError: sys.meta_path is None, Python is likely shutting down
Exception ignored in: <function ReaderBase.__del__ at 0x2b482c2eb820>
Traceback (most recent call last):
  File "/home/ejakupov/mdanalysis/package/MDAnalysis/coordinates/base.py", line 2161, in __del__
  File "/home/ejakupov/mdanalysis/package/MDAnalysis/coordinates/H5MD.py", line 718, in close
  File "/home/ejakupov/.conda/envs/mda2/lib/python3.8/site-packages/h5py-2.9.0-py3.8-linux-x86_64.egg/h5py/_hl/files.py", line 412, in close
  File "h5py/_objects.pyx", line 54, in h5py._objects.with_phil.wrapper
  File "h5py/_objects.pyx", line 55, in h5py._objects.with_phil.wrapper
  File "h5py/h5f.pyx", line 264, in h5py.h5f.get_obj_ids
  File "h5py/h5i.pyx", line 43, in h5py.h5i.wrap_identifier
ImportError: sys.meta_path is None, Python is likely shutting down
Exception ignored in: <function ReaderBase.__del__ at 0x2aab6e12a820>
Traceback (most recent call last):
  File "/home/ejakupov/mdanalysis/package/MDAnalysis/coordinates/base.py", line 2161, in __del__
  File "/home/ejakupov/mdanalysis/package/MDAnalysis/coordinates/H5MD.py", line 718, in close
  File "/home/ejakupov/.conda/envs/mda2/lib/python3.8/site-packages/h5py-2.9.0-py3.8-linux-x86_64.egg/h5py/_hl/files.py", line 412, in close
  File "h5py/_objects.pyx", line 54, in h5py._objects.with_phil.wrapper
  File "h5py/_objects.pyx", line 55, in h5py._objects.with_phil.wrapper
  File "h5py/h5f.pyx", line 264, in h5py.h5f.get_obj_ids
  File "h5py/h5i.pyx", line 43, in h5py.h5i.wrap_identifier
ImportError: sys.meta_path is None, Python is likely shutting down
Exception ignored in: <function ReaderBase.__del__ at 0x2b4ef8803820>
Traceback (most recent call last):
  File "/home/ejakupov/mdanalysis/package/MDAnalysis/coordinates/base.py", line 2161, in __del__
  File "/home/ejakupov/mdanalysis/package/MDAnalysis/coordinates/H5MD.py", line 718, in close
  File "/home/ejakupov/.conda/envs/mda2/lib/python3.8/site-packages/h5py-2.9.0-py3.8-linux-x86_64.egg/h5py/_hl/files.py", line 412, in close
  File "h5py/_objects.pyx", line 54, in h5py._objects.with_phil.wrapper
  File "h5py/_objects.pyx", line 55, in h5py._objects.with_phil.wrapper
  File "h5py/h5f.pyx", line 264, in h5py.h5f.get_obj_ids
  File "h5py/h5i.pyx", line 43, in h5py.h5i.wrap_identifier
ImportError: sys.meta_path is None, Python is likely shutting down
Exception ignored in: <function ReaderBase.__del__ at 0x2b2288512820>
Traceback (most recent call last):
  File "/home/ejakupov/mdanalysis/package/MDAnalysis/coordinates/base.py", line 2161, in __del__
  File "/home/ejakupov/mdanalysis/package/MDAnalysis/coordinates/H5MD.py", line 718, in close
  File "/home/ejakupov/.conda/envs/mda2/lib/python3.8/site-packages/h5py-2.9.0-py3.8-linux-x86_64.egg/h5py/_hl/files.py", line 412, in close
  File "h5py/_objects.pyx", line 54, in h5py._objects.with_phil.wrapper
  File "h5py/_objects.pyx", line 55, in h5py._objects.with_phil.wrapper
  File "h5py/h5f.pyx", line 264, in h5py.h5f.get_obj_ids
  File "h5py/h5i.pyx", line 43, in h5py.h5i.wrap_identifier
ImportError: sys.meta_path is None, Python is likely shutting down
Exception ignored in: <function ReaderBase.__del__ at 0x2afb44e7e820>
Traceback (most recent call last):
  File "/home/ejakupov/mdanalysis/package/MDAnalysis/coordinates/base.py", line 2161, in __del__
  File "/home/ejakupov/mdanalysis/package/MDAnalysis/coordinates/H5MD.py", line 718, in close
  File "/home/ejakupov/.conda/envs/mda2/lib/python3.8/site-packages/h5py-2.9.0-py3.8-linux-x86_64.egg/h5py/_hl/files.py", line 412, in close
  File "h5py/_objects.pyx", line 54, in h5py._objects.with_phil.wrapper
  File "h5py/_objects.pyx", line 55, in h5py._objects.with_phil.wrapper
  File "h5py/h5f.pyx", line 264, in h5py.h5f.get_obj_ids
  File "h5py/h5i.pyx", line 43, in h5py.h5i.wrap_identifier
ImportError: sys.meta_path is None, Python is likely shutting down
Exception ignored in: <function ReaderBase.__del__ at 0x2b9bad175820>
Traceback (most recent call last):
  File "/home/ejakupov/mdanalysis/package/MDAnalysis/coordinates/base.py", line 2161, in __del__
  File "/home/ejakupov/mdanalysis/package/MDAnalysis/coordinates/H5MD.py", line 718, in close
  File "/home/ejakupov/.conda/envs/mda2/lib/python3.8/site-packages/h5py-2.9.0-py3.8-linux-x86_64.egg/h5py/_hl/files.py", line 412, in close
  File "h5py/_objects.pyx", line 54, in h5py._objects.with_phil.wrapper
  File "h5py/_objects.pyx", line 55, in h5py._objects.with_phil.wrapper
  File "h5py/h5f.pyx", line 264, in h5py.h5f.get_obj_ids
  File "h5py/h5i.pyx", line 43, in h5py.h5i.wrap_identifier
ImportError: sys.meta_path is None, Python is likely shutting down
Exception ignored in: <function ReaderBase.__del__ at 0x2ab8aac13820>
Traceback (most recent call last):
  File "/home/ejakupov/mdanalysis/package/MDAnalysis/coordinates/base.py", line 2161, in __del__
  File "/home/ejakupov/mdanalysis/package/MDAnalysis/coordinates/H5MD.py", line 718, in close
  File "/home/ejakupov/.conda/envs/mda2/lib/python3.8/site-packages/h5py-2.9.0-py3.8-linux-x86_64.egg/h5py/_hl/files.py", line 412, in close
  File "h5py/_objects.pyx", line 54, in h5py._objects.with_phil.wrapper
  File "h5py/_objects.pyx", line 55, in h5py._objects.with_phil.wrapper
  File "h5py/h5f.pyx", line 264, in h5py.h5f.get_obj_ids
  File "h5py/h5i.pyx", line 43, in h5py.h5i.wrap_identifier
ImportError: sys.meta_path is None, Python is likely shutting down
Exception ignored in: <function ReaderBase.__del__ at 0x2b0f4db9b820>
Traceback (most recent call last):
  File "/home/ejakupov/mdanalysis/package/MDAnalysis/coordinates/base.py", line 2161, in __del__
  File "/home/ejakupov/mdanalysis/package/MDAnalysis/coordinates/H5MD.py", line 718, in close
  File "/home/ejakupov/.conda/envs/mda2/lib/python3.8/site-packages/h5py-2.9.0-py3.8-linux-x86_64.egg/h5py/_hl/files.py", line 412, in close
  File "h5py/_objects.pyx", line 54, in h5py._objects.with_phil.wrapper
  File "h5py/_objects.pyx", line 55, in h5py._objects.with_phil.wrapper
  File "h5py/h5f.pyx", line 264, in h5py.h5f.get_obj_ids
  File "h5py/h5i.pyx", line 43, in h5py.h5i.wrap_identifier
ImportError: sys.meta_path is None, Python is likely shutting down
Exception ignored in: <function ReaderBase.__del__ at 0x2b68290a5820>
Traceback (most recent call last):
  File "/home/ejakupov/mdanalysis/package/MDAnalysis/coordinates/base.py", line 2161, in __del__
  File "/home/ejakupov/mdanalysis/package/MDAnalysis/coordinates/H5MD.py", line 718, in close
  File "/home/ejakupov/.conda/envs/mda2/lib/python3.8/site-packages/h5py-2.9.0-py3.8-linux-x86_64.egg/h5py/_hl/files.py", line 412, in close
  File "h5py/_objects.pyx", line 54, in h5py._objects.with_phil.wrapper
  File "h5py/_objects.pyx", line 55, in h5py._objects.with_phil.wrapper
  File "h5py/h5f.pyx", line 264, in h5py.h5f.get_obj_ids
  File "h5py/h5i.pyx", line 43, in h5py.h5i.wrap_identifier
ImportError: sys.meta_path is None, Python is likely shutting down
Exception ignored in: <function ReaderBase.__del__ at 0x2b6618d55820>
Traceback (most recent call last):
  File "/home/ejakupov/mdanalysis/package/MDAnalysis/coordinates/base.py", line 2161, in __del__
  File "/home/ejakupov/mdanalysis/package/MDAnalysis/coordinates/H5MD.py", line 718, in close
  File "/home/ejakupov/.conda/envs/mda2/lib/python3.8/site-packages/h5py-2.9.0-py3.8-linux-x86_64.egg/h5py/_hl/files.py", line 412, in close
  File "h5py/_objects.pyx", line 54, in h5py._objects.with_phil.wrapper
  File "h5py/_objects.pyx", line 55, in h5py._objects.with_phil.wrapper
  File "h5py/h5f.pyx", line 264, in h5py.h5f.get_obj_ids
  File "h5py/h5i.pyx", line 43, in h5py.h5i.wrap_identifier
ImportError: sys.meta_path is None, Python is likely shutting down
Exception ignored in: <function ReaderBase.__del__ at 0x2ab892197820>
Traceback (most recent call last):
  File "/home/ejakupov/mdanalysis/package/MDAnalysis/coordinates/base.py", line 2161, in __del__
  File "/home/ejakupov/mdanalysis/package/MDAnalysis/coordinates/H5MD.py", line 718, in close
  File "/home/ejakupov/.conda/envs/mda2/lib/python3.8/site-packages/h5py-2.9.0-py3.8-linux-x86_64.egg/h5py/_hl/files.py", line 412, in close
  File "h5py/_objects.pyx", line 54, in h5py._objects.with_phil.wrapper
  File "h5py/_objects.pyx", line 55, in h5py._objects.with_phil.wrapper
  File "h5py/h5f.pyx", line 264, in h5py.h5f.get_obj_ids
  File "h5py/h5i.pyx", line 43, in h5py.h5i.wrap_identifier
ImportError: sys.meta_path is None, Python is likely shutting down
Exception ignored in: <function ReaderBase.__del__ at 0x2b031baeb820>
Traceback (most recent call last):
  File "/home/ejakupov/mdanalysis/package/MDAnalysis/coordinates/base.py", line 2161, in __del__
  File "/home/ejakupov/mdanalysis/package/MDAnalysis/coordinates/H5MD.py", line 718, in close
  File "/home/ejakupov/.conda/envs/mda2/lib/python3.8/site-packages/h5py-2.9.0-py3.8-linux-x86_64.egg/h5py/_hl/files.py", line 412, in close
  File "h5py/_objects.pyx", line 54, in h5py._objects.with_phil.wrapper
  File "h5py/_objects.pyx", line 55, in h5py._objects.with_phil.wrapper
  File "h5py/h5f.pyx", line 264, in h5py.h5f.get_obj_ids
  File "h5py/h5i.pyx", line 43, in h5py.h5i.wrap_identifier
ImportError: sys.meta_path is None, Python is likely shutting down
Exception ignored in: <function ReaderBase.__del__ at 0x2b4dedb7e820>
Traceback (most recent call last):
  File "/home/ejakupov/mdanalysis/package/MDAnalysis/coordinates/base.py", line 2161, in __del__
  File "/home/ejakupov/mdanalysis/package/MDAnalysis/coordinates/H5MD.py", line 718, in close
  File "/home/ejakupov/.conda/envs/mda2/lib/python3.8/site-packages/h5py-2.9.0-py3.8-linux-x86_64.egg/h5py/_hl/files.py", line 412, in close
  File "h5py/_objects.pyx", line 54, in h5py._objects.with_phil.wrapper
  File "h5py/_objects.pyx", line 55, in h5py._objects.with_phil.wrapper
  File "h5py/h5f.pyx", line 264, in h5py.h5f.get_obj_ids
  File "h5py/h5i.pyx", line 43, in h5py.h5i.wrap_identifier
ImportError: sys.meta_path is None, Python is likely shutting down
Exception ignored in: <function ReaderBase.__del__ at 0x2b63d933b820>
Traceback (most recent call last):
  File "/home/ejakupov/mdanalysis/package/MDAnalysis/coordinates/base.py", line 2161, in __del__
  File "/home/ejakupov/mdanalysis/package/MDAnalysis/coordinates/H5MD.py", line 718, in close
  File "/home/ejakupov/.conda/envs/mda2/lib/python3.8/site-packages/h5py-2.9.0-py3.8-linux-x86_64.egg/h5py/_hl/files.py", line 412, in close
  File "h5py/_objects.pyx", line 54, in h5py._objects.with_phil.wrapper
  File "h5py/_objects.pyx", line 55, in h5py._objects.with_phil.wrapper
  File "h5py/h5f.pyx", line 264, in h5py.h5f.get_obj_ids
  File "h5py/h5i.pyx", line 43, in h5py.h5i.wrap_identifier
ImportError: sys.meta_path is None, Python is likely shutting down
Exception ignored in: <function ReaderBase.__del__ at 0x2acc2d44e820>
Traceback (most recent call last):
  File "/home/ejakupov/mdanalysis/package/MDAnalysis/coordinates/base.py", line 2161, in __del__
  File "/home/ejakupov/mdanalysis/package/MDAnalysis/coordinates/H5MD.py", line 718, in close
  File "/home/ejakupov/.conda/envs/mda2/lib/python3.8/site-packages/h5py-2.9.0-py3.8-linux-x86_64.egg/h5py/_hl/files.py", line 412, in close
  File "h5py/_objects.pyx", line 54, in h5py._objects.with_phil.wrapper
  File "h5py/_objects.pyx", line 55, in h5py._objects.with_phil.wrapper
  File "h5py/h5f.pyx", line 264, in h5py.h5f.get_obj_ids
  File "h5py/h5i.pyx", line 43, in h5py.h5i.wrap_identifier
ImportError: sys.meta_path is None, Python is likely shutting down
Exception ignored in: <function ReaderBase.__del__ at 0x2ba31ae59820>
Traceback (most recent call last):
  File "/home/ejakupov/mdanalysis/package/MDAnalysis/coordinates/base.py", line 2161, in __del__
  File "/home/ejakupov/mdanalysis/package/MDAnalysis/coordinates/H5MD.py", line 718, in close
  File "/home/ejakupov/.conda/envs/mda2/lib/python3.8/site-packages/h5py-2.9.0-py3.8-linux-x86_64.egg/h5py/_hl/files.py", line 412, in close
  File "h5py/_objects.pyx", line 54, in h5py._objects.with_phil.wrapper
  File "h5py/_objects.pyx", line 55, in h5py._objects.with_phil.wrapper
  File "h5py/h5f.pyx", line 264, in h5py.h5f.get_obj_ids
  File "h5py/h5i.pyx", line 43, in h5py.h5i.wrap_identifier
ImportError: sys.meta_path is None, Python is likely shutting down
Exception ignored in: <function ReaderBase.__del__ at 0x2b8a84674820>
Traceback (most recent call last):
  File "/home/ejakupov/mdanalysis/package/MDAnalysis/coordinates/base.py", line 2161, in __del__
  File "/home/ejakupov/mdanalysis/package/MDAnalysis/coordinates/H5MD.py", line 718, in close
  File "/home/ejakupov/.conda/envs/mda2/lib/python3.8/site-packages/h5py-2.9.0-py3.8-linux-x86_64.egg/h5py/_hl/files.py", line 412, in close
  File "h5py/_objects.pyx", line 54, in h5py._objects.with_phil.wrapper
  File "h5py/_objects.pyx", line 55, in h5py._objects.with_phil.wrapper
  File "h5py/h5f.pyx", line 264, in h5py.h5f.get_obj_ids
  File "h5py/h5i.pyx", line 43, in h5py.h5i.wrap_identifier
ImportError: sys.meta_path is None, Python is likely shutting down
Exception ignored in: <function ReaderBase.__del__ at 0x2b7d8e757820>
Traceback (most recent call last):
  File "/home/ejakupov/mdanalysis/package/MDAnalysis/coordinates/base.py", line 2161, in __del__
  File "/home/ejakupov/mdanalysis/package/MDAnalysis/coordinates/H5MD.py", line 718, in close
  File "/home/ejakupov/.conda/envs/mda2/lib/python3.8/site-packages/h5py-2.9.0-py3.8-linux-x86_64.egg/h5py/_hl/files.py", line 412, in close
  File "h5py/_objects.pyx", line 54, in h5py._objects.with_phil.wrapper
  File "h5py/_objects.pyx", line 55, in h5py._objects.with_phil.wrapper
  File "h5py/h5f.pyx", line 264, in h5py.h5f.get_obj_ids
  File "h5py/h5i.pyx", line 43, in h5py.h5i.wrap_identifier
ImportError: sys.meta_path is None, Python is likely shutting down
Exception ignored in: <function ReaderBase.__del__ at 0x2ae16172d820>
Traceback (most recent call last):
  File "/home/ejakupov/mdanalysis/package/MDAnalysis/coordinates/base.py", line 2161, in __del__
  File "/home/ejakupov/mdanalysis/package/MDAnalysis/coordinates/H5MD.py", line 718, in close
  File "/home/ejakupov/.conda/envs/mda2/lib/python3.8/site-packages/h5py-2.9.0-py3.8-linux-x86_64.egg/h5py/_hl/files.py", line 412, in close
  File "h5py/_objects.pyx", line 54, in h5py._objects.with_phil.wrapper
  File "h5py/_objects.pyx", line 55, in h5py._objects.with_phil.wrapper
  File "h5py/h5f.pyx", line 264, in h5py.h5f.get_obj_ids
  File "h5py/h5i.pyx", line 43, in h5py.h5i.wrap_identifier
ImportError: sys.meta_path is None, Python is likely shutting down
Traceback (most recent call last):
  File "h5py/_objects.pyx", line 193, in h5py._objects.ObjectID.__dealloc__
RuntimeError: Can't decrement id ref count (can't close file, there are objects still open)
Exception ignored in: 'h5py._objects.ObjectID.__dealloc__'
Traceback (most recent call last):
  File "h5py/_objects.pyx", line 193, in h5py._objects.ObjectID.__dealloc__
RuntimeError: Can't decrement id ref count (can't close file, there are objects still open)
Exception ignored in: <function ReaderBase.__del__ at 0x2b71403c4820>
Traceback (most recent call last):
  File "/home/ejakupov/mdanalysis/package/MDAnalysis/coordinates/base.py", line 2161, in __del__
  File "/home/ejakupov/mdanalysis/package/MDAnalysis/coordinates/H5MD.py", line 718, in close
  File "/home/ejakupov/.conda/envs/mda2/lib/python3.8/site-packages/h5py-2.9.0-py3.8-linux-x86_64.egg/h5py/_hl/files.py", line 412, in close
  File "h5py/_objects.pyx", line 54, in h5py._objects.with_phil.wrapper
  File "h5py/_objects.pyx", line 55, in h5py._objects.with_phil.wrapper
  File "h5py/h5f.pyx", line 264, in h5py.h5f.get_obj_ids
  File "h5py/h5i.pyx", line 43, in h5py.h5i.wrap_identifier
ImportError: sys.meta_path is None, Python is likely shutting down
Traceback (most recent call last):
  File "h5py/_objects.pyx", line 193, in h5py._objects.ObjectID.__dealloc__
RuntimeError: Can't decrement id ref count (can't close file, there are objects still open)
Exception ignored in: 'h5py._objects.ObjectID.__dealloc__'
Traceback (most recent call last):
  File "h5py/_objects.pyx", line 193, in h5py._objects.ObjectID.__dealloc__
RuntimeError: Can't decrement id ref count (can't close file, there are objects still open)
Traceback (most recent call last):
  File "h5py/_objects.pyx", line 193, in h5py._objects.ObjectID.__dealloc__
RuntimeError: Can't decrement id ref count (can't close file, there are objects still open)
Exception ignored in: 'h5py._objects.ObjectID.__dealloc__'
Traceback (most recent call last):
  File "h5py/_objects.pyx", line 193, in h5py._objects.ObjectID.__dealloc__
RuntimeError: Can't decrement id ref count (can't close file, there are objects still open)
Traceback (most recent call last):
  File "h5py/_objects.pyx", line 193, in h5py._objects.ObjectID.__dealloc__
RuntimeError: Can't decrement id ref count (can't close file, there are objects still open)
Traceback (most recent call last):
  File "h5py/_objects.pyx", line 193, in h5py._objects.ObjectID.__dealloc__
RuntimeError: Can't decrement id ref count (can't close file, there are objects still open)
Exception ignored in: 'h5py._objects.ObjectID.__dealloc__'
Traceback (most recent call last):
  File "h5py/_objects.pyx", line 193, in h5py._objects.ObjectID.__dealloc__
RuntimeError: Can't decrement id ref count (can't close file, there are objects still open)
Exception ignored in: 'h5py._objects.ObjectID.__dealloc__'
Traceback (most recent call last):
  File "h5py/_objects.pyx", line 193, in h5py._objects.ObjectID.__dealloc__
RuntimeError: Can't decrement id ref count (can't close file, there are objects still open)
Exception ignored in: <function ReaderBase.__del__ at 0x2b648f858820>
Traceback (most recent call last):
  File "/home/ejakupov/mdanalysis/package/MDAnalysis/coordinates/base.py", line 2161, in __del__
  File "/home/ejakupov/mdanalysis/package/MDAnalysis/coordinates/H5MD.py", line 718, in close
  File "/home/ejakupov/.conda/envs/mda2/lib/python3.8/site-packages/h5py-2.9.0-py3.8-linux-x86_64.egg/h5py/_hl/files.py", line 412, in close
  File "h5py/_objects.pyx", line 54, in h5py._objects.with_phil.wrapper
  File "h5py/_objects.pyx", line 55, in h5py._objects.with_phil.wrapper
  File "h5py/h5f.pyx", line 264, in h5py.h5f.get_obj_ids
  File "h5py/h5i.pyx", line 43, in h5py.h5i.wrap_identifier
ImportError: sys.meta_path is None, Python is likely shutting down
Exception ignored in: <function ReaderBase.__del__ at 0x2b843a7eb820>
Traceback (most recent call last):
  File "/home/ejakupov/mdanalysis/package/MDAnalysis/coordinates/base.py", line 2161, in __del__
  File "/home/ejakupov/mdanalysis/package/MDAnalysis/coordinates/H5MD.py", line 718, in close
  File "/home/ejakupov/.conda/envs/mda2/lib/python3.8/site-packages/h5py-2.9.0-py3.8-linux-x86_64.egg/h5py/_hl/files.py", line 412, in close
  File "h5py/_objects.pyx", line 54, in h5py._objects.with_phil.wrapper
  File "h5py/_objects.pyx", line 55, in h5py._objects.with_phil.wrapper
  File "h5py/h5f.pyx", line 264, in h5py.h5f.get_obj_ids
  File "h5py/h5i.pyx", line 43, in h5py.h5i.wrap_identifier
ImportError: sys.meta_path is None, Python is likely shutting down
Traceback (most recent call last):
  File "h5py/_objects.pyx", line 193, in h5py._objects.ObjectID.__dealloc__
RuntimeError: Can't decrement id ref count (can't close file, there are objects still open)
Exception ignored in: 'h5py._objects.ObjectID.__dealloc__'
Traceback (most recent call last):
  File "h5py/_objects.pyx", line 193, in h5py._objects.ObjectID.__dealloc__
RuntimeError: Can't decrement id ref count (can't close file, there are objects still open)
Traceback (most recent call last):
  File "h5py/_objects.pyx", line 193, in h5py._objects.ObjectID.__dealloc__
RuntimeError: Can't decrement id ref count (can't close file, there are objects still open)
Exception ignored in: 'h5py._objects.ObjectID.__dealloc__'
Traceback (most recent call last):
  File "h5py/_objects.pyx", line 193, in h5py._objects.ObjectID.__dealloc__
RuntimeError: Can't decrement id ref count (can't close file, there are objects still open)
Exception ignored in: <function ReaderBase.__del__ at 0x2b809c7d0820>
Traceback (most recent call last):
  File "/home/ejakupov/mdanalysis/package/MDAnalysis/coordinates/base.py", line 2161, in __del__
  File "/home/ejakupov/mdanalysis/package/MDAnalysis/coordinates/H5MD.py", line 718, in close
  File "/home/ejakupov/.conda/envs/mda2/lib/python3.8/site-packages/h5py-2.9.0-py3.8-linux-x86_64.egg/h5py/_hl/files.py", line 412, in close
  File "h5py/_objects.pyx", line 54, in h5py._objects.with_phil.wrapper
  File "h5py/_objects.pyx", line 55, in h5py._objects.with_phil.wrapper
  File "h5py/h5f.pyx", line 264, in h5py.h5f.get_obj_ids
  File "h5py/h5i.pyx", line 43, in h5py.h5i.wrap_identifier
ImportError: sys.meta_path is None, Python is likely shutting down
Exception ignored in: <function ReaderBase.__del__ at 0x2b3edd50a820>
Traceback (most recent call last):
  File "/home/ejakupov/mdanalysis/package/MDAnalysis/coordinates/base.py", line 2161, in __del__
  File "/home/ejakupov/mdanalysis/package/MDAnalysis/coordinates/H5MD.py", line 718, in close
  File "/home/ejakupov/.conda/envs/mda2/lib/python3.8/site-packages/h5py-2.9.0-py3.8-linux-x86_64.egg/h5py/_hl/files.py", line 412, in close
  File "h5py/_objects.pyx", line 54, in h5py._objects.with_phil.wrapper
  File "h5py/_objects.pyx", line 55, in h5py._objects.with_phil.wrapper
  File "h5py/h5f.pyx", line 264, in h5py.h5f.get_obj_ids
  File "h5py/h5i.pyx", line 43, in h5py.h5i.wrap_identifier
ImportError: sys.meta_path is None, Python is likely shutting down
Traceback (most recent call last):
  File "h5py/_objects.pyx", line 193, in h5py._objects.ObjectID.__dealloc__
RuntimeError: Can't decrement id ref count (can't close file, there are objects still open)
Exception ignored in: 'h5py._objects.ObjectID.__dealloc__'
Traceback (most recent call last):
  File "h5py/_objects.pyx", line 193, in h5py._objects.ObjectID.__dealloc__
RuntimeError: Can't decrement id ref count (can't close file, there are objects still open)
Exception ignored in: <function ReaderBase.__del__ at 0x2b19acaa9820>
Traceback (most recent call last):
  File "/home/ejakupov/mdanalysis/package/MDAnalysis/coordinates/base.py", line 2161, in __del__
  File "/home/ejakupov/mdanalysis/package/MDAnalysis/coordinates/H5MD.py", line 718, in close
  File "/home/ejakupov/.conda/envs/mda2/lib/python3.8/site-packages/h5py-2.9.0-py3.8-linux-x86_64.egg/h5py/_hl/files.py", line 412, in close
  File "h5py/_objects.pyx", line 54, in h5py._objects.with_phil.wrapper
  File "h5py/_objects.pyx", line 55, in h5py._objects.with_phil.wrapper
  File "h5py/h5f.pyx", line 264, in h5py.h5f.get_obj_ids
  File "h5py/h5i.pyx", line 43, in h5py.h5i.wrap_identifier
ImportError: sys.meta_path is None, Python is likely shutting down
Exception ignored in: <function ReaderBase.__del__ at 0x2adf840fb820>
Traceback (most recent call last):
  File "/home/ejakupov/mdanalysis/package/MDAnalysis/coordinates/base.py", line 2161, in __del__
  File "/home/ejakupov/mdanalysis/package/MDAnalysis/coordinates/H5MD.py", line 718, in close
  File "/home/ejakupov/.conda/envs/mda2/lib/python3.8/site-packages/h5py-2.9.0-py3.8-linux-x86_64.egg/h5py/_hl/files.py", line 412, in close
  File "h5py/_objects.pyx", line 54, in h5py._objects.with_phil.wrapper
  File "h5py/_objects.pyx", line 55, in h5py._objects.with_phil.wrapper
  File "h5py/h5f.pyx", line 264, in h5py.h5f.get_obj_ids
  File "h5py/h5i.pyx", line 43, in h5py.h5i.wrap_identifier
ImportError: sys.meta_path is None, Python is likely shutting down
Exception ignored in: <function ReaderBase.__del__ at 0x2b63aa1fc820>
Traceback (most recent call last):
  File "/home/ejakupov/mdanalysis/package/MDAnalysis/coordinates/base.py", line 2161, in __del__
  File "/home/ejakupov/mdanalysis/package/MDAnalysis/coordinates/H5MD.py", line 718, in close
  File "/home/ejakupov/.conda/envs/mda2/lib/python3.8/site-packages/h5py-2.9.0-py3.8-linux-x86_64.egg/h5py/_hl/files.py", line 412, in close
  File "h5py/_objects.pyx", line 54, in h5py._objects.with_phil.wrapper
  File "h5py/_objects.pyx", line 55, in h5py._objects.with_phil.wrapper
  File "h5py/h5f.pyx", line 264, in h5py.h5f.get_obj_ids
  File "h5py/h5i.pyx", line 43, in h5py.h5i.wrap_identifier
ImportError: sys.meta_path is None, Python is likely shutting down
Exception ignored in: <function ReaderBase.__del__ at 0x2b7b332dd820>
Traceback (most recent call last):
  File "/home/ejakupov/mdanalysis/package/MDAnalysis/coordinates/base.py", line 2161, in __del__
  File "/home/ejakupov/mdanalysis/package/MDAnalysis/coordinates/H5MD.py", line 718, in close
  File "/home/ejakupov/.conda/envs/mda2/lib/python3.8/site-packages/h5py-2.9.0-py3.8-linux-x86_64.egg/h5py/_hl/files.py", line 412, in close
  File "h5py/_objects.pyx", line 54, in h5py._objects.with_phil.wrapper
  File "h5py/_objects.pyx", line 55, in h5py._objects.with_phil.wrapper
  File "h5py/h5f.pyx", line 264, in h5py.h5f.get_obj_ids
  File "h5py/h5i.pyx", line 43, in h5py.h5i.wrap_identifier
ImportError: sys.meta_path is None, Python is likely shutting down
Traceback (most recent call last):
  File "h5py/_objects.pyx", line 193, in h5py._objects.ObjectID.__dealloc__
RuntimeError: Can't decrement id ref count (can't close file, there are objects still open)
Exception ignored in: 'h5py._objects.ObjectID.__dealloc__'
Traceback (most recent call last):
  File "h5py/_objects.pyx", line 193, in h5py._objects.ObjectID.__dealloc__
RuntimeError: Can't decrement id ref count (can't close file, there are objects still open)
Traceback (most recent call last):
  File "h5py/_objects.pyx", line 193, in h5py._objects.ObjectID.__dealloc__
RuntimeError: Can't decrement id ref count (can't close file, there are objects still open)
Exception ignored in: 'h5py._objects.ObjectID.__dealloc__'
Traceback (most recent call last):
  File "h5py/_objects.pyx", line 193, in h5py._objects.ObjectID.__dealloc__
RuntimeError: Can't decrement id ref count (can't close file, there are objects still open)
Traceback (most recent call last):
  File "h5py/_objects.pyx", line 193, in h5py._objects.ObjectID.__dealloc__
RuntimeError: Can't decrement id ref count (can't close file, there are objects still open)
Exception ignored in: 'h5py._objects.ObjectID.__dealloc__'
Traceback (most recent call last):
  File "h5py/_objects.pyx", line 193, in h5py._objects.ObjectID.__dealloc__
RuntimeError: Can't decrement id ref count (can't close file, there are objects still open)
Exception ignored in: <function ReaderBase.__del__ at 0x2b2645257820>
Traceback (most recent call last):
  File "/home/ejakupov/mdanalysis/package/MDAnalysis/coordinates/base.py", line 2161, in __del__
  File "/home/ejakupov/mdanalysis/package/MDAnalysis/coordinates/H5MD.py", line 718, in close
  File "/home/ejakupov/.conda/envs/mda2/lib/python3.8/site-packages/h5py-2.9.0-py3.8-linux-x86_64.egg/h5py/_hl/files.py", line 412, in close
  File "h5py/_objects.pyx", line 54, in h5py._objects.with_phil.wrapper
  File "h5py/_objects.pyx", line 55, in h5py._objects.with_phil.wrapper
  File "h5py/h5f.pyx", line 264, in h5py.h5f.get_obj_ids
  File "h5py/h5i.pyx", line 43, in h5py.h5i.wrap_identifier
ImportError: sys.meta_path is None, Python is likely shutting down
Traceback (most recent call last):
  File "h5py/_objects.pyx", line 193, in h5py._objects.ObjectID.__dealloc__
RuntimeError: Can't decrement id ref count (can't close file, there are objects still open)
Exception ignored in: 'h5py._objects.ObjectID.__dealloc__'
Traceback (most recent call last):
  File "h5py/_objects.pyx", line 193, in h5py._objects.ObjectID.__dealloc__
RuntimeError: Can't decrement id ref count (can't close file, there are objects still open)
Exception ignored in: <function ReaderBase.__del__ at 0x2b949934d820>
Traceback (most recent call last):
  File "/home/ejakupov/mdanalysis/package/MDAnalysis/coordinates/base.py", line 2161, in __del__
  File "/home/ejakupov/mdanalysis/package/MDAnalysis/coordinates/H5MD.py", line 718, in close
  File "/home/ejakupov/.conda/envs/mda2/lib/python3.8/site-packages/h5py-2.9.0-py3.8-linux-x86_64.egg/h5py/_hl/files.py", line 412, in close
  File "h5py/_objects.pyx", line 54, in h5py._objects.with_phil.wrapper
  File "h5py/_objects.pyx", line 55, in h5py._objects.with_phil.wrapper
  File "h5py/h5f.pyx", line 264, in h5py.h5f.get_obj_ids
  File "h5py/h5i.pyx", line 43, in h5py.h5i.wrap_identifier
ImportError: sys.meta_path is None, Python is likely shutting down
Exception ignored in: <function ReaderBase.__del__ at 0x2ab7e71f3820>
Traceback (most recent call last):
  File "/home/ejakupov/mdanalysis/package/MDAnalysis/coordinates/base.py", line 2161, in __del__
  File "/home/ejakupov/mdanalysis/package/MDAnalysis/coordinates/H5MD.py", line 718, in close
  File "/home/ejakupov/.conda/envs/mda2/lib/python3.8/site-packages/h5py-2.9.0-py3.8-linux-x86_64.egg/h5py/_hl/files.py", line 412, in close
  File "h5py/_objects.pyx", line 54, in h5py._objects.with_phil.wrapper
  File "h5py/_objects.pyx", line 55, in h5py._objects.with_phil.wrapper
  File "h5py/h5f.pyx", line 264, in h5py.h5f.get_obj_ids
  File "h5py/h5i.pyx", line 43, in h5py.h5i.wrap_identifier
ImportError: sys.meta_path is None, Python is likely shutting down
Traceback (most recent call last):
  File "h5py/_objects.pyx", line 193, in h5py._objects.ObjectID.__dealloc__
RuntimeError: Can't decrement id ref count (can't close file, there are objects still open)
Exception ignored in: 'h5py._objects.ObjectID.__dealloc__'
Traceback (most recent call last):
  File "h5py/_objects.pyx", line 193, in h5py._objects.ObjectID.__dealloc__
RuntimeError: Can't decrement id ref count (can't close file, there are objects still open)
Traceback (most recent call last):
  File "h5py/_objects.pyx", line 193, in h5py._objects.ObjectID.__dealloc__
RuntimeError: Can't decrement id ref count (can't close file, there are objects still open)
Exception ignored in: 'h5py._objects.ObjectID.__dealloc__'
Traceback (most recent call last):
  File "h5py/_objects.pyx", line 193, in h5py._objects.ObjectID.__dealloc__
RuntimeError: Can't decrement id ref count (can't close file, there are objects still open)
Traceback (most recent call last):
  File "h5py/_objects.pyx", line 193, in h5py._objects.ObjectID.__dealloc__
RuntimeError: Can't decrement id ref count (can't close file, there are objects still open)
Exception ignored in: 'h5py._objects.ObjectID.__dealloc__'
Traceback (most recent call last):
  File "h5py/_objects.pyx", line 193, in h5py._objects.ObjectID.__dealloc__
RuntimeError: Can't decrement id ref count (can't close file, there are objects still open)
Exception ignored in: <function ReaderBase.__del__ at 0x2b8aa432c820>
Traceback (most recent call last):
  File "/home/ejakupov/mdanalysis/package/MDAnalysis/coordinates/base.py", line 2161, in __del__
  File "/home/ejakupov/mdanalysis/package/MDAnalysis/coordinates/H5MD.py", line 718, in close
  File "/home/ejakupov/.conda/envs/mda2/lib/python3.8/site-packages/h5py-2.9.0-py3.8-linux-x86_64.egg/h5py/_hl/files.py", line 412, in close
  File "h5py/_objects.pyx", line 54, in h5py._objects.with_phil.wrapper
  File "h5py/_objects.pyx", line 55, in h5py._objects.with_phil.wrapper
  File "h5py/h5f.pyx", line 264, in h5py.h5f.get_obj_ids
  File "h5py/h5i.pyx", line 43, in h5py.h5i.wrap_identifier
ImportError: sys.meta_path is None, Python is likely shutting down
Exception ignored in: <function ReaderBase.__del__ at 0x2b43833ef820>
Traceback (most recent call last):
  File "/home/ejakupov/mdanalysis/package/MDAnalysis/coordinates/base.py", line 2161, in __del__
  File "/home/ejakupov/mdanalysis/package/MDAnalysis/coordinates/H5MD.py", line 718, in close
  File "/home/ejakupov/.conda/envs/mda2/lib/python3.8/site-packages/h5py-2.9.0-py3.8-linux-x86_64.egg/h5py/_hl/files.py", line 412, in close
  File "h5py/_objects.pyx", line 54, in h5py._objects.with_phil.wrapper
  File "h5py/_objects.pyx", line 55, in h5py._objects.with_phil.wrapper
  File "h5py/h5f.pyx", line 264, in h5py.h5f.get_obj_ids
  File "h5py/h5i.pyx", line 43, in h5py.h5i.wrap_identifier
ImportError: sys.meta_path is None, Python is likely shutting down
Traceback (most recent call last):
  File "h5py/_objects.pyx", line 193, in h5py._objects.ObjectID.__dealloc__
RuntimeError: Can't decrement id ref count (can't close file, there are objects still open)
Exception ignored in: 'h5py._objects.ObjectID.__dealloc__'
Traceback (most recent call last):
  File "h5py/_objects.pyx", line 193, in h5py._objects.ObjectID.__dealloc__
RuntimeError: Can't decrement id ref count (can't close file, there are objects still open)
Exception ignored in: <function ReaderBase.__del__ at 0x2b836929f820>
Traceback (most recent call last):
  File "/home/ejakupov/mdanalysis/package/MDAnalysis/coordinates/base.py", line 2161, in __del__
  File "/home/ejakupov/mdanalysis/package/MDAnalysis/coordinates/H5MD.py", line 718, in close
  File "/home/ejakupov/.conda/envs/mda2/lib/python3.8/site-packages/h5py-2.9.0-py3.8-linux-x86_64.egg/h5py/_hl/files.py", line 412, in close
  File "h5py/_objects.pyx", line 54, in h5py._objects.with_phil.wrapper
  File "h5py/_objects.pyx", line 55, in h5py._objects.with_phil.wrapper
  File "h5py/h5f.pyx", line 264, in h5py.h5f.get_obj_ids
  File "h5py/h5i.pyx", line 43, in h5py.h5i.wrap_identifier
ImportError: sys.meta_path is None, Python is likely shutting down
Traceback (most recent call last):
  File "h5py/_objects.pyx", line 193, in h5py._objects.ObjectID.__dealloc__
RuntimeError: Can't decrement id ref count (can't close file, there are objects still open)
Exception ignored in: 'h5py._objects.ObjectID.__dealloc__'
Traceback (most recent call last):
  File "h5py/_objects.pyx", line 193, in h5py._objects.ObjectID.__dealloc__
RuntimeError: Can't decrement id ref count (can't close file, there are objects still open)
Traceback (most recent call last):
  File "h5py/_objects.pyx", line 193, in h5py._objects.ObjectID.__dealloc__
RuntimeError: Can't decrement id ref count (can't close file, there are objects still open)
Exception ignored in: 'h5py._objects.ObjectID.__dealloc__'
Traceback (most recent call last):
  File "h5py/_objects.pyx", line 193, in h5py._objects.ObjectID.__dealloc__
RuntimeError: Can't decrement id ref count (can't close file, there are objects still open)
Exception ignored in: <function ReaderBase.__del__ at 0x2acd78410820>
Traceback (most recent call last):
  File "/home/ejakupov/mdanalysis/package/MDAnalysis/coordinates/base.py", line 2161, in __del__
  File "/home/ejakupov/mdanalysis/package/MDAnalysis/coordinates/H5MD.py", line 718, in close
  File "/home/ejakupov/.conda/envs/mda2/lib/python3.8/site-packages/h5py-2.9.0-py3.8-linux-x86_64.egg/h5py/_hl/files.py", line 412, in close
  File "h5py/_objects.pyx", line 54, in h5py._objects.with_phil.wrapper
  File "h5py/_objects.pyx", line 55, in h5py._objects.with_phil.wrapper
  File "h5py/h5f.pyx", line 264, in h5py.h5f.get_obj_ids
  File "h5py/h5i.pyx", line 43, in h5py.h5i.wrap_identifier
ImportError: sys.meta_path is None, Python is likely shutting down
Traceback (most recent call last):
  File "h5py/_objects.pyx", line 193, in h5py._objects.ObjectID.__dealloc__
RuntimeError: Can't decrement id ref count (can't close file, there are objects still open)
Exception ignored in: 'h5py._objects.ObjectID.__dealloc__'
Traceback (most recent call last):
  File "h5py/_objects.pyx", line 193, in h5py._objects.ObjectID.__dealloc__
RuntimeError: Can't decrement id ref count (can't close file, there are objects still open)
Traceback (most recent call last):
  File "h5py/_objects.pyx", line 193, in h5py._objects.ObjectID.__dealloc__
RuntimeError: Can't decrement id ref count (can't close file, there are objects still open)
Exception ignored in: 'h5py._objects.ObjectID.__dealloc__'
Traceback (most recent call last):
  File "h5py/_objects.pyx", line 193, in h5py._objects.ObjectID.__dealloc__
RuntimeError: Can't decrement id ref count (can't close file, there are objects still open)
Traceback (most recent call last):
  File "h5py/_objects.pyx", line 193, in h5py._objects.ObjectID.__dealloc__
RuntimeError: Can't decrement id ref count (can't close file, there are objects still open)
Exception ignored in: 'h5py._objects.ObjectID.__dealloc__'
Traceback (most recent call last):
  File "h5py/_objects.pyx", line 193, in h5py._objects.ObjectID.__dealloc__
RuntimeError: Can't decrement id ref count (can't close file, there are objects still open)
Traceback (most recent call last):
  File "h5py/_objects.pyx", line 193, in h5py._objects.ObjectID.__dealloc__
RuntimeError: Can't decrement id ref count (can't close file, there are objects still open)
Exception ignored in: 'h5py._objects.ObjectID.__dealloc__'
Traceback (most recent call last):
  File "h5py/_objects.pyx", line 193, in h5py._objects.ObjectID.__dealloc__
RuntimeError: Can't decrement id ref count (can't close file, there are objects still open)
Traceback (most recent call last):
  File "h5py/_objects.pyx", line 193, in h5py._objects.ObjectID.__dealloc__
RuntimeError: Can't decrement id ref count (can't close file, there are objects still open)
Exception ignored in: 'h5py._objects.ObjectID.__dealloc__'
Traceback (most recent call last):
  File "h5py/_objects.pyx", line 193, in h5py._objects.ObjectID.__dealloc__
RuntimeError: Can't decrement id ref count (can't close file, there are objects still open)
Traceback (most recent call last):
  File "h5py/_objects.pyx", line 193, in h5py._objects.ObjectID.__dealloc__
RuntimeError: Can't decrement id ref count (can't close file, there are objects still open)
Exception ignored in: 'h5py._objects.ObjectID.__dealloc__'
Traceback (most recent call last):
  File "h5py/_objects.pyx", line 193, in h5py._objects.ObjectID.__dealloc__
RuntimeError: Can't decrement id ref count (can't close file, there are objects still open)
Traceback (most recent call last):
  File "h5py/_objects.pyx", line 193, in h5py._objects.ObjectID.__dealloc__
RuntimeError: Can't decrement id ref count (can't close file, there are objects still open)
Exception ignored in: 'h5py._objects.ObjectID.__dealloc__'
Traceback (most recent call last):
  File "h5py/_objects.pyx", line 193, in h5py._objects.ObjectID.__dealloc__
RuntimeError: Can't decrement id ref count (can't close file, there are objects still open)
Traceback (most recent call last):
  File "h5py/_objects.pyx", line 193, in h5py._objects.ObjectID.__dealloc__
RuntimeError: Can't decrement id ref count (can't close file, there are objects still open)
Exception ignored in: 'h5py._objects.ObjectID.__dealloc__'
Traceback (most recent call last):
  File "h5py/_objects.pyx", line 193, in h5py._objects.ObjectID.__dealloc__
RuntimeError: Can't decrement id ref count (can't close file, there are objects still open)
Traceback (most recent call last):
  File "h5py/_objects.pyx", line 193, in h5py._objects.ObjectID.__dealloc__
RuntimeError: Can't decrement id ref count (can't close file, there are objects still open)
Exception ignored in: 'h5py._objects.ObjectID.__dealloc__'
Traceback (most recent call last):
  File "h5py/_objects.pyx", line 193, in h5py._objects.ObjectID.__dealloc__
RuntimeError: Can't decrement id ref count (can't close file, there are objects still open)
Traceback (most recent call last):
  File "h5py/_objects.pyx", line 193, in h5py._objects.ObjectID.__dealloc__
RuntimeError: Can't decrement id ref count (can't close file, there are objects still open)
Exception ignored in: 'h5py._objects.ObjectID.__dealloc__'
Traceback (most recent call last):
  File "h5py/_objects.pyx", line 193, in h5py._objects.ObjectID.__dealloc__
RuntimeError: Can't decrement id ref count (can't close file, there are objects still open)
Traceback (most recent call last):
  File "h5py/_objects.pyx", line 193, in h5py._objects.ObjectID.__dealloc__
RuntimeError: Can't decrement id ref count (can't close file, there are objects still open)
Exception ignored in: 'h5py._objects.ObjectID.__dealloc__'
Traceback (most recent call last):
  File "h5py/_objects.pyx", line 193, in h5py._objects.ObjectID.__dealloc__
RuntimeError: Can't decrement id ref count (can't close file, there are objects still open)
Traceback (most recent call last):
  File "h5py/_objects.pyx", line 193, in h5py._objects.ObjectID.__dealloc__
RuntimeError: Can't decrement id ref count (can't close file, there are objects still open)
Exception ignored in: 'h5py._objects.ObjectID.__dealloc__'
Traceback (most recent call last):
  File "h5py/_objects.pyx", line 193, in h5py._objects.ObjectID.__dealloc__
RuntimeError: Can't decrement id ref count (can't close file, there are objects still open)
Traceback (most recent call last):
  File "h5py/_objects.pyx", line 193, in h5py._objects.ObjectID.__dealloc__
RuntimeError: Can't decrement id ref count (can't close file, there are objects still open)
Exception ignored in: 'h5py._objects.ObjectID.__dealloc__'
Traceback (most recent call last):
  File "h5py/_objects.pyx", line 193, in h5py._objects.ObjectID.__dealloc__
RuntimeError: Can't decrement id ref count (can't close file, there are objects still open)
Exception ignored in: <function ReaderBase.__del__ at 0x2b7f64582820>
Traceback (most recent call last):
  File "/home/ejakupov/mdanalysis/package/MDAnalysis/coordinates/base.py", line 2161, in __del__
  File "/home/ejakupov/mdanalysis/package/MDAnalysis/coordinates/H5MD.py", line 718, in close
  File "/home/ejakupov/.conda/envs/mda2/lib/python3.8/site-packages/h5py-2.9.0-py3.8-linux-x86_64.egg/h5py/_hl/files.py", line 412, in close
  File "h5py/_objects.pyx", line 54, in h5py._objects.with_phil.wrapper
  File "h5py/_objects.pyx", line 55, in h5py._objects.with_phil.wrapper
  File "h5py/h5f.pyx", line 264, in h5py.h5f.get_obj_ids
  File "h5py/h5i.pyx", line 43, in h5py.h5i.wrap_identifier
ImportError: sys.meta_path is None, Python is likely shutting down
Traceback (most recent call last):
  File "h5py/_objects.pyx", line 193, in h5py._objects.ObjectID.__dealloc__
RuntimeError: Can't decrement id ref count (can't close file, there are objects still open)
Exception ignored in: 'h5py._objects.ObjectID.__dealloc__'
Traceback (most recent call last):
  File "h5py/_objects.pyx", line 193, in h5py._objects.ObjectID.__dealloc__
RuntimeError: Can't decrement id ref count (can't close file, there are objects still open)
Traceback (most recent call last):
  File "h5py/_objects.pyx", line 193, in h5py._objects.ObjectID.__dealloc__
RuntimeError: Can't decrement id ref count (can't close file, there are objects still open)
Exception ignored in: 'h5py._objects.ObjectID.__dealloc__'
Traceback (most recent call last):
  File "h5py/_objects.pyx", line 193, in h5py._objects.ObjectID.__dealloc__
RuntimeError: Can't decrement id ref count (can't close file, there are objects still open)
Exception ignored in: <function ReaderBase.__del__ at 0x2ac428b48820>
Traceback (most recent call last):
  File "/home/ejakupov/mdanalysis/package/MDAnalysis/coordinates/base.py", line 2161, in __del__
  File "/home/ejakupov/mdanalysis/package/MDAnalysis/coordinates/H5MD.py", line 718, in close
  File "/home/ejakupov/.conda/envs/mda2/lib/python3.8/site-packages/h5py-2.9.0-py3.8-linux-x86_64.egg/h5py/_hl/files.py", line 412, in close
  File "h5py/_objects.pyx", line 54, in h5py._objects.with_phil.wrapper
  File "h5py/_objects.pyx", line 55, in h5py._objects.with_phil.wrapper
  File "h5py/h5f.pyx", line 264, in h5py.h5f.get_obj_ids
  File "h5py/h5i.pyx", line 43, in h5py.h5i.wrap_identifier
ImportError: sys.meta_path is None, Python is likely shutting down
Exception ignored in: <function ReaderBase.__del__ at 0x2b15b13eb820>
Traceback (most recent call last):
  File "/home/ejakupov/mdanalysis/package/MDAnalysis/coordinates/base.py", line 2161, in __del__
  File "/home/ejakupov/mdanalysis/package/MDAnalysis/coordinates/H5MD.py", line 718, in close
  File "/home/ejakupov/.conda/envs/mda2/lib/python3.8/site-packages/h5py-2.9.0-py3.8-linux-x86_64.egg/h5py/_hl/files.py", line 412, in close
  File "h5py/_objects.pyx", line 54, in h5py._objects.with_phil.wrapper
  File "h5py/_objects.pyx", line 55, in h5py._objects.with_phil.wrapper
  File "h5py/h5f.pyx", line 264, in h5py.h5f.get_obj_ids
  File "h5py/h5i.pyx", line 43, in h5py.h5i.wrap_identifier
ImportError: sys.meta_path is None, Python is likely shutting down
Traceback (most recent call last):
  File "h5py/_objects.pyx", line 193, in h5py._objects.ObjectID.__dealloc__
RuntimeError: Can't decrement id ref count (can't close file, there are objects still open)
Exception ignored in: 'h5py._objects.ObjectID.__dealloc__'
Traceback (most recent call last):
  File "h5py/_objects.pyx", line 193, in h5py._objects.ObjectID.__dealloc__
RuntimeError: Can't decrement id ref count (can't close file, there are objects still open)
Traceback (most recent call last):
  File "h5py/_objects.pyx", line 193, in h5py._objects.ObjectID.__dealloc__
RuntimeError: Can't decrement id ref count (can't close file, there are objects still open)
Exception ignored in: 'h5py._objects.ObjectID.__dealloc__'
Traceback (most recent call last):
  File "h5py/_objects.pyx", line 193, in h5py._objects.ObjectID.__dealloc__
RuntimeError: Can't decrement id ref count (can't close file, there are objects still open)
Exception ignored in: <function ReaderBase.__del__ at 0x2b44193a9820>
Traceback (most recent call last):
  File "/home/ejakupov/mdanalysis/package/MDAnalysis/coordinates/base.py", line 2161, in __del__
  File "/home/ejakupov/mdanalysis/package/MDAnalysis/coordinates/H5MD.py", line 718, in close
  File "/home/ejakupov/.conda/envs/mda2/lib/python3.8/site-packages/h5py-2.9.0-py3.8-linux-x86_64.egg/h5py/_hl/files.py", line 412, in close
  File "h5py/_objects.pyx", line 54, in h5py._objects.with_phil.wrapper
  File "h5py/_objects.pyx", line 55, in h5py._objects.with_phil.wrapper
  File "h5py/h5f.pyx", line 264, in h5py.h5f.get_obj_ids
  File "h5py/h5i.pyx", line 43, in h5py.h5i.wrap_identifier
ImportError: sys.meta_path is None, Python is likely shutting down
Traceback (most recent call last):
  File "h5py/_objects.pyx", line 193, in h5py._objects.ObjectID.__dealloc__
RuntimeError: Can't decrement id ref count (can't close file, there are objects still open)
Exception ignored in: 'h5py._objects.ObjectID.__dealloc__'
Traceback (most recent call last):
  File "h5py/_objects.pyx", line 193, in h5py._objects.ObjectID.__dealloc__
RuntimeError: Can't decrement id ref count (can't close file, there are objects still open)
Traceback (most recent call last):
  File "h5py/_objects.pyx", line 193, in h5py._objects.ObjectID.__dealloc__
RuntimeError: Can't decrement id ref count (can't close file, there are objects still open)
Exception ignored in: 'h5py._objects.ObjectID.__dealloc__'
Traceback (most recent call last):
  File "h5py/_objects.pyx", line 193, in h5py._objects.ObjectID.__dealloc__
RuntimeError: Can't decrement id ref count (can't close file, there are objects still open)
Traceback (most recent call last):
  File "h5py/_objects.pyx", line 193, in h5py._objects.ObjectID.__dealloc__
RuntimeError: Can't decrement id ref count (can't close file, there are objects still open)
Exception ignored in: 'h5py._objects.ObjectID.__dealloc__'
Traceback (most recent call last):
  File "h5py/_objects.pyx", line 193, in h5py._objects.ObjectID.__dealloc__
RuntimeError: Can't decrement id ref count (can't close file, there are objects still open)
Traceback (most recent call last):
  File "h5py/_objects.pyx", line 193, in h5py._objects.ObjectID.__dealloc__
RuntimeError: Can't decrement id ref count (can't close file, there are objects still open)
Exception ignored in: 'h5py._objects.ObjectID.__dealloc__'
Traceback (most recent call last):
  File "h5py/_objects.pyx", line 193, in h5py._objects.ObjectID.__dealloc__
RuntimeError: Can't decrement id ref count (can't close file, there are objects still open)
Traceback (most recent call last):
  File "h5py/_objects.pyx", line 193, in h5py._objects.ObjectID.__dealloc__
RuntimeError: Can't decrement id ref count (can't close file, there are objects still open)
Exception ignored in: 'h5py._objects.ObjectID.__dealloc__'
Traceback (most recent call last):
  File "h5py/_objects.pyx", line 193, in h5py._objects.ObjectID.__dealloc__
RuntimeError: Can't decrement id ref count (can't close file, there are objects still open)
Traceback (most recent call last):
  File "h5py/_objects.pyx", line 193, in h5py._objects.ObjectID.__dealloc__
RuntimeError: Can't decrement id ref count (can't close file, there are objects still open)
Exception ignored in: 'h5py._objects.ObjectID.__dealloc__'
Traceback (most recent call last):
  File "h5py/_objects.pyx", line 193, in h5py._objects.ObjectID.__dealloc__
RuntimeError: Can't decrement id ref count (can't close file, there are objects still open)
Traceback (most recent call last):
  File "h5py/_objects.pyx", line 193, in h5py._objects.ObjectID.__dealloc__
RuntimeError: Can't decrement id ref count (can't close file, there are objects still open)
Exception ignored in: 'h5py._objects.ObjectID.__dealloc__'
Traceback (most recent call last):
  File "h5py/_objects.pyx", line 193, in h5py._objects.ObjectID.__dealloc__
RuntimeError: Can't decrement id ref count (can't close file, there are objects still open)
Traceback (most recent call last):
  File "h5py/_objects.pyx", line 193, in h5py._objects.ObjectID.__dealloc__
RuntimeError: Can't decrement id ref count (can't close file, there are objects still open)
Exception ignored in: 'h5py._objects.ObjectID.__dealloc__'
Traceback (most recent call last):
  File "h5py/_objects.pyx", line 193, in h5py._objects.ObjectID.__dealloc__
RuntimeError: Can't decrement id ref count (can't close file, there are objects still open)
Exception ignored in: <function ReaderBase.__del__ at 0x2b9b46d72820>
Traceback (most recent call last):
  File "/home/ejakupov/mdanalysis/package/MDAnalysis/coordinates/base.py", line 2161, in __del__
  File "/home/ejakupov/mdanalysis/package/MDAnalysis/coordinates/H5MD.py", line 718, in close
  File "/home/ejakupov/.conda/envs/mda2/lib/python3.8/site-packages/h5py-2.9.0-py3.8-linux-x86_64.egg/h5py/_hl/files.py", line 412, in close
  File "h5py/_objects.pyx", line 54, in h5py._objects.with_phil.wrapper
  File "h5py/_objects.pyx", line 55, in h5py._objects.with_phil.wrapper
  File "h5py/h5f.pyx", line 264, in h5py.h5f.get_obj_ids
  File "h5py/h5i.pyx", line 43, in h5py.h5i.wrap_identifier
ImportError: sys.meta_path is None, Python is likely shutting down
Traceback (most recent call last):
  File "h5py/_objects.pyx", line 193, in h5py._objects.ObjectID.__dealloc__
RuntimeError: Can't decrement id ref count (can't close file, there are objects still open)
Exception ignored in: 'h5py._objects.ObjectID.__dealloc__'
Traceback (most recent call last):
  File "h5py/_objects.pyx", line 193, in h5py._objects.ObjectID.__dealloc__
RuntimeError: Can't decrement id ref count (can't close file, there are objects still open)
Traceback (most recent call last):
  File "h5py/_objects.pyx", line 193, in h5py._objects.ObjectID.__dealloc__
RuntimeError: Can't decrement id ref count (can't close file, there are objects still open)
Exception ignored in: 'h5py._objects.ObjectID.__dealloc__'
Traceback (most recent call last):
  File "h5py/_objects.pyx", line 193, in h5py._objects.ObjectID.__dealloc__
RuntimeError: Can't decrement id ref count (can't close file, there are objects still open)
Traceback (most recent call last):
  File "h5py/_objects.pyx", line 193, in h5py._objects.ObjectID.__dealloc__
RuntimeError: Can't decrement id ref count (can't close file, there are objects still open)
Exception ignored in: 'h5py._objects.ObjectID.__dealloc__'
Traceback (most recent call last):
  File "h5py/_objects.pyx", line 193, in h5py._objects.ObjectID.__dealloc__
RuntimeError: Can't decrement id ref count (can't close file, there are objects still open)
Traceback (most recent call last):
  File "h5py/_objects.pyx", line 193, in h5py._objects.ObjectID.__dealloc__
RuntimeError: Can't decrement id ref count (can't close file, there are objects still open)
Exception ignored in: 'h5py._objects.ObjectID.__dealloc__'
Traceback (most recent call last):
  File "h5py/_objects.pyx", line 193, in h5py._objects.ObjectID.__dealloc__
RuntimeError: Can't decrement id ref count (can't close file, there are objects still open)
Exception ignored in: <function ReaderBase.__del__ at 0x2aeaf6c47820>
Traceback (most recent call last):
  File "/home/ejakupov/mdanalysis/package/MDAnalysis/coordinates/base.py", line 2161, in __del__
  File "/home/ejakupov/mdanalysis/package/MDAnalysis/coordinates/H5MD.py", line 718, in close
  File "/home/ejakupov/.conda/envs/mda2/lib/python3.8/site-packages/h5py-2.9.0-py3.8-linux-x86_64.egg/h5py/_hl/files.py", line 412, in close
  File "h5py/_objects.pyx", line 54, in h5py._objects.with_phil.wrapper
  File "h5py/_objects.pyx", line 55, in h5py._objects.with_phil.wrapper
  File "h5py/h5f.pyx", line 264, in h5py.h5f.get_obj_ids
  File "h5py/h5i.pyx", line 43, in h5py.h5i.wrap_identifier
ImportError: sys.meta_path is None, Python is likely shutting down
Traceback (most recent call last):
  File "h5py/_objects.pyx", line 193, in h5py._objects.ObjectID.__dealloc__
RuntimeError: Can't decrement id ref count (can't close file, there are objects still open)
Exception ignored in: 'h5py._objects.ObjectID.__dealloc__'
Traceback (most recent call last):
  File "h5py/_objects.pyx", line 193, in h5py._objects.ObjectID.__dealloc__
RuntimeError: Can't decrement id ref count (can't close file, there are objects still open)
Traceback (most recent call last):
  File "h5py/_objects.pyx", line 193, in h5py._objects.ObjectID.__dealloc__
RuntimeError: Can't decrement id ref count (can't close file, there are objects still open)
Exception ignored in: 'h5py._objects.ObjectID.__dealloc__'
Traceback (most recent call last):
  File "h5py/_objects.pyx", line 193, in h5py._objects.ObjectID.__dealloc__
RuntimeError: Can't decrement id ref count (can't close file, there are objects still open)
Traceback (most recent call last):
  File "h5py/_objects.pyx", line 193, in h5py._objects.ObjectID.__dealloc__
RuntimeError: Can't decrement id ref count (can't close file, there are objects still open)
Exception ignored in: 'h5py._objects.ObjectID.__dealloc__'
Traceback (most recent call last):
  File "h5py/_objects.pyx", line 193, in h5py._objects.ObjectID.__dealloc__
RuntimeError: Can't decrement id ref count (can't close file, there are objects still open)
Traceback (most recent call last):
  File "h5py/_objects.pyx", line 193, in h5py._objects.ObjectID.__dealloc__
RuntimeError: Can't decrement id ref count (can't close file, there are objects still open)
Exception ignored in: 'h5py._objects.ObjectID.__dealloc__'
Traceback (most recent call last):
  File "h5py/_objects.pyx", line 193, in h5py._objects.ObjectID.__dealloc__
RuntimeError: Can't decrement id ref count (can't close file, there are objects still open)
Traceback (most recent call last):
  File "h5py/_objects.pyx", line 193, in h5py._objects.ObjectID.__dealloc__
RuntimeError: Can't decrement id ref count (can't close file, there are objects still open)
Exception ignored in: 'h5py._objects.ObjectID.__dealloc__'
Traceback (most recent call last):
  File "h5py/_objects.pyx", line 193, in h5py._objects.ObjectID.__dealloc__
RuntimeError: Can't decrement id ref count (can't close file, there are objects still open)
Traceback (most recent call last):
  File "h5py/_objects.pyx", line 193, in h5py._objects.ObjectID.__dealloc__
RuntimeError: Can't decrement id ref count (can't close file, there are objects still open)
Exception ignored in: 'h5py._objects.ObjectID.__dealloc__'
Traceback (most recent call last):
  File "h5py/_objects.pyx", line 193, in h5py._objects.ObjectID.__dealloc__
RuntimeError: Can't decrement id ref count (can't close file, there are objects still open)
Traceback (most recent call last):
  File "h5py/_objects.pyx", line 193, in h5py._objects.ObjectID.__dealloc__
RuntimeError: Can't decrement id ref count (can't close file, there are objects still open)
Exception ignored in: 'h5py._objects.ObjectID.__dealloc__'
Traceback (most recent call last):
  File "h5py/_objects.pyx", line 193, in h5py._objects.ObjectID.__dealloc__
RuntimeError: Can't decrement id ref count (can't close file, there are objects still open)
Exception ignored in: <function ReaderBase.__del__ at 0x2b32b4621820>
Traceback (most recent call last):
  File "/home/ejakupov/mdanalysis/package/MDAnalysis/coordinates/base.py", line 2161, in __del__
  File "/home/ejakupov/mdanalysis/package/MDAnalysis/coordinates/H5MD.py", line 718, in close
  File "/home/ejakupov/.conda/envs/mda2/lib/python3.8/site-packages/h5py-2.9.0-py3.8-linux-x86_64.egg/h5py/_hl/files.py", line 412, in close
  File "h5py/_objects.pyx", line 54, in h5py._objects.with_phil.wrapper
  File "h5py/_objects.pyx", line 55, in h5py._objects.with_phil.wrapper
  File "h5py/h5f.pyx", line 264, in h5py.h5f.get_obj_ids
  File "h5py/h5i.pyx", line 43, in h5py.h5i.wrap_identifier
ImportError: sys.meta_path is None, Python is likely shutting down
Traceback (most recent call last):
  File "h5py/_objects.pyx", line 193, in h5py._objects.ObjectID.__dealloc__
RuntimeError: Can't decrement id ref count (can't close file, there are objects still open)
Exception ignored in: 'h5py._objects.ObjectID.__dealloc__'
Traceback (most recent call last):
  File "h5py/_objects.pyx", line 193, in h5py._objects.ObjectID.__dealloc__
RuntimeError: Can't decrement id ref count (can't close file, there are objects still open)
slurmstepd: error: *** JOB 7077960 ON cg13-12 CANCELLED AT 2021-01-06T05:25:12 ***
